Workbook

Sheet Cover
A1: Sheikh Najjar Solar PV Project: Financial Model
A3: Fictional sponsor: Halab Solar Development Company (SPV). Prepared by Yamen Agha as a portfolio feasibility study.
A4: All figures in nominal US dollars unless stated. Annual model, operating years 1-25 after construction (year 0).
A6: Sheet guide
A7: Inputs Every assumption with unit, basis (Sourced / Derived / Assumption) and source ID (see Sources sheet).
A8: Capex Capital cost build-up and funding plan (debt sizing, fees, interest during construction).
A9: CashFlow 25-year operating, tax, debt and cash-flow waterfall. All cells are live formulas.
A10: Returns NPV, IRR (project and equity), payback, LCOE, DSCR and LLCR.
A11: Market Grid tariff and diesel cost comparators; blended cost by hours of grid supply.
A12: Analysis Scenario, tornado and Monte Carlo results exported from the Python scripts (static values).
A13: Checks Integrity checks and reconciliation of this workbook against the Python reference model.
A14: Sources Dated source list.
... A17: Scenario levers on Inputs: yield_mult, capex_mult, opex_mult and bess_on (0 = PV only, 1 = PV + BESS).

Sheet Inputs
A1: Name | B1: Value | C1: Unit | D1: Basis | E1: Source | F1: Note
A2: lat | B2: 36.27 | C2: deg N | D2: Assumption | E2: S33 | F2: Indicative site inside/adjacent to Sheikh Najjar Industrial City; existing PV plant reported at 36.2701N, 37.2569E
A3: lon | B3: 37.3 | C3: deg E | D3: Assumption | E3: S33 | F3: Indicative coordinates used for all resource queries
A4: pvgis_yield | B4: 1654.53 | C4: kWh/kWp/yr | D4: Sourced | E4: S01 | F4: PVGIS 5.3, SARAH3 2005-2023, fixed 31 deg optimal tilt, 14% system loss
A5: pvgis_sd_y | B5: 41 | C5: kWh/kWp/yr | D5: Sourced | E5: S01 | F5: Year-to-year standard deviation reported by PVGIS
A6: gsa_pvout | B6: 1761.3 | C6: kWh/kWp/yr | D6: Sourced | E6: S04 | F6: Global Solar Atlas PVOUT (Solargis model), cross-check only
A7: model_uncert | B7: 0.05 | C7: fraction (1 sigma) | D7: Assumption | F7: Resource and modelling uncertainty used for P90 and Monte Carlo
A8: mwp | B8: 60 | C8: MWp DC | D8: Assumption | F8: About a third of base-case estimated daytime zone demand (range 21-54%) so output is fully absorbed
A9: mwac | B9: 50 | C9: MWac | D9: Assumption | F9: DC/AC ratio 1.20
A10: availability | B10: 0.985 | C10: fraction | D10: Assumption | F10: Plant and offtaker-network availability; below the 99%+ typical in stable markets
A11: deg_y1 | B11: 0.01 | C11: fraction | D11: Sourced | E11: S09 | F11: Jinko Tiger Neo warranty: max 1.0% in year 1
A12: deg_annual | B12: 0.004 | C12: fraction/yr | D12: Sourced | E12: S09 | F12: Jinko Tiger Neo warranty: 0.4%/yr years 2-30
A13: land_ha_per_mwp | B13: 1.3 | C13: ha/MWp | D13: Assumption | E13: S32 | F13: Existing Sheikh Najjar plant: 33 MW on 35 ha (1.06 ha/MW); 1.3 used for wider row spacing
A14: c_modules | B14: 0.114 | C14: USD/Wp | D14: Sourced | E14: S05 | F14: InfoLink 30 Sep 2026: TOPCon module average, non-China markets, before tax
A15: c_logistics | B15: 0.012 | C15: USD/Wp | D15: Assumption | F15: Sea freight, insurance, Latakia port handling and inland haulage to Aleppo (about 10% of FOB)
A16: c_inverters | B16: 0.03 | C16: USD/Wp | D16: Assumption | E16: S08 | F16: PowerChina 2024 bids averaged 0.013 USD/W in China; export, delivery and spares margin applied
A17: c_structure | B17: 0.065 | C17: USD/Wp | D17: Assumption | F17: Fixed-tilt galvanised steel mounting incl. piling
A18: c_elec_bos | B18: 0.055 | C18: USD/Wp | D18: Assumption | F18: DC/AC cabling, combiner boxes, earthing, MV collection
A19: c_substation_lump | B19: 4000000 | C19: USD | D19: Assumption | E19: S37 | F19: Step-up substation and connection into the zone 20 kV network; zone already has 60 MW and 30 MW substations added in 2023
A20: c_civil | B20: 0.035 | C20: USD/Wp | D20: Assumption | F20: Site preparation, roads, drainage, fencing
A21: c_install | B21: 0.04 | C21: USD/Wp | D21: Assumption | F21: Mechanical and electrical installation labour
A22: c_security_scada | B22: 0.012 | C22: USD/Wp | D22: Assumption | F22: CCTV, intrusion detection, SCADA, weather station
A23: epc_margin | B23: 0.08 | C23: fraction of hard cost | D23: Assumption | F23: EPC overhead and margin
A24: c_dev_lump | B24: 1200000 | C24: USD | D24: Assumption | F24: Feasibility, ESIA, legal, PPA negotiation, permits
A25: owners_pct | B25: 0.015 | C25: fraction of EPC | D25: Assumption | F25: Owner's engineer and construction all-risk insurance
A26: contingency | B26: 0.1 | C26: fraction of EPC | D26: Assumption | F26: Elevated for country risk and logistics
A27: om_per_kwp | B27: 9 | C27: USD/kWp/yr | D27: Assumption | E27: S10 | F27: O&M contract incl. cleaning; NREL ATB 2024 benchmark is 22 USD/kWac/yr all-in fixed O&M
A28: insurance_pct | B28: 0.006 | C28: fraction of capex/yr | D28: Assumption | F28: Property and business interruption insurance
A29: pri_pct_debt | B29: 0.008 | C29: fraction of initial debt/yr | D29: Assumption | F29: Political risk insurance premium on senior debt
A30: security_fix | B30: 250000 | C30: USD/yr | D30: Assumption | F30: Guarding and patrols
A31: land_lease_per_ha | B31: 600 | C31: USD/ha/yr | D31: Assumption | F31: Lease of industrial-city land
A32: admin_fix | B32: 300000 | C32: USD/yr | D32: Assumption | F32: SPV management, audit, billing, metering
A33: wheeling | B33: 0.005 | C33: USD/kWh | D33: Assumption | E33: S18 | F33: Network use/metering charge for delivery over the zone distribution network
A34: opex_esc | B34: 0.025 | C34: fraction/yr | D34: Assumption | F34: Opex escalation in USD
A35: inverter_repl_yr | B35: 13 | C35: operating year | D35: Assumption | F35: Inverter replacement
A36: inverter_repl_cost | B36: 0.025 | C36: USD/Wp | D36: Assumption | E36: S08 | F36: Replacement cost in nominal USD
A37: ppa_day | B37: 0.1 | C37: USD/kWh | D37: Assumption | E37: S11 | F37: USD-indexed PPA invoiced in SYP at the CBS official rate; 28% below the 17 SYP/kWh industrial grid tariff
A38: ppa_esc | B38: 0.01 | C38: fraction/yr | D38: Assumption | F38: Annual PPA indexation
A39: collection | B39: 0.97 | C39: fraction | D39: Assumption | F39: Share of invoices collected (bad debt 3%)
A40: fx_haircut | B40: 0.03 | C40: fraction | D40: Assumption | E40: S15 | F40: Expected loss converting SYP receipts to USD; official-parallel gap was 12.8% on 13 Oct 2026
...

Sheet Capex
A1: Item | B1: USD | C1: USD/Wp | D1: Formula basis
A2: PV modules (TOPCon, bifacial) | B2: =in_c_modules*in_mwp*1000000 -> 6840000 | C2: =B2/(in_mwp*1000000) -> 0.114 | D2: module price x Wp
A3: Freight, insurance, port and inland logistics | B3: =in_c_logistics*in_mwp*1000000 -> 720000 | C3: =B3/(in_mwp*1000000) -> 0.012
A4: Inverters | B4: =in_c_inverters*in_mwp*1000000 -> 1800000 | C4: =B4/(in_mwp*1000000) -> 0.03
A5: Mounting structures | B5: =in_c_structure*in_mwp*1000000 -> 3900000 | C5: =B5/(in_mwp*1000000) -> 0.065
A6: Electrical balance of system | B6: =in_c_elec_bos*in_mwp*1000000 -> 3300000 | C6: =B6/(in_mwp*1000000) -> 0.055
A7: Substation and interconnection | B7: =in_c_substation_lump -> 4000000 | C7: =B7/(in_mwp*1000000) -> 0.066666667 | D7: lump sum
A8: Civil works and fencing | B8: =in_c_civil*in_mwp*1000000 -> 2100000 | C8: =B8/(in_mwp*1000000) -> 0.035
A9: Installation labour | B9: =in_c_install*in_mwp*1000000 -> 2400000 | C9: =B9/(in_mwp*1000000) -> 0.04
A10: Security systems and SCADA | B10: =in_c_security_scada*in_mwp*1000000 -> 720000 | C10: =B10/(in_mwp*1000000) -> 0.012
A11: Hard cost subtotal | B11: =SUM(B2:B10) -> 25780000 | C11: =B11/(in_mwp*1000000) -> 0.42966667
A12: EPC overhead and margin | B12: =B11*in_epc_margin -> 2062400 | C12: =B12/(in_mwp*1000000) -> 0.034373333
A13: EPC price | B13: =B11+B12 -> 27842400 | C13: =B13/(in_mwp*1000000) -> 0.46404
A14: Development and permitting | B14: =in_c_dev_lump -> 1200000 | C14: =B14/(in_mwp*1000000) -> 0.02
A15: Owner's engineer and construction insurance | B15: =B13*in_owners_pct -> 417636 | C15: =B15/(in_mwp*1000000) -> 0.0069606
A16: Contingency | B16: =B13*in_contingency -> 2784240 | C16: =B16/(in_mwp*1000000) -> 0.046404
A17: Capex multiplier (scenario lever) | B17: =in_capex_mult -> 1
A18: PV capex | B18: =(B13+B14+B15+B16)*B17 -> 32244276 | C18: =B18/(in_mwp*1000000) -> 0.5374046
A19: BESS capex (option) | B19: =in_bess_on*in_bess_mwh*1000*in_bess_capex_kwh*in_capex_mult -> 0 | C19: =B19/(in_mwp*1000000) -> 0
A20: Total capex (C) | B20: =B18+B19 -> 32244276 | C20: =B20/(in_mwp*1000000) -> 0.5374046
A22: Funding plan
A23: Cost of debt (7-yr UST + margin) | B23: =in_ust7+in_debt_margin -> 0.0961
A24: Senior debt (D) | B24: =in_gearing*x_capex/(1-in_gearing*(in_upfront_fee+x_kd*in_idc_factor)) -> 20170111
A25: Upfront fees | B25: =in_upfront_fee*x_debt -> 403402.22
A26: Interest during construction | B26: =x_kd*in_idc_factor*x_debt -> 969173.85
A27: Total funding requirement (F) | B27: =x_capex+x_fee+x_idc -> 33616852
A28: Equity (F - D) | B28: =x_funding-x_debt -> 13446741
A29: Gearing check (D / F) | B29: =x_debt/x_funding -> 0.6
A30: Annual debt service (annuity) | B30: =-PMT(x_kd,in_tenor,x_debt) -> 2903912.4
A31: Capex per kWp (USD) | B31: =x_capex/(in_mwp*1000) -> 537.4046
A32: Capex per kWac (USD) | B32: =x_capex/(in_mwac*1000) -> 644.88552

Sheet CashFlow
A1: Line item | B1: Unit | D1: Year 0 | E1: Year 1 | F1: Year 2 | G1: Year 3 | H1: Year 4 | I1: Year 5 | J1: Year 6 | K1: Year 7 | L1: Year 8 | M1: Year 9 | N1: Year 10 | O1: Year 11 | P1: Year 12 | Q1: Year 13 | R1: Year 14 | S1: Year 15 | T1: Year 16 | U1: Year 17 | V1: Year 18 | W1: Year 19 | X1: Year 20 | Y1: Year 21 | Z1: Year 22 | AA1: Year 23 | AB1: Year 24 | AC1: Year 25
A3: Timeline
A4: Operating year | D4: 0 | E4: 1 | F4: 2 | G4: 3 | H4: 4 | I4: 5 | J4: 6 | K4: 7 | L4: 8 | M4: 9 | N4: 10 | O4: 11 | P4: 12 | Q4: 13 | R4: 14 | S4: 15 | T4: 16 | U4: 17 | V4: 18 | W4: 19 | X4: 20 | Y4: 21 | Z4: 22 | AA4: 23 | AB4: 24 | AC4: 25
A5: Calendar year of COD anniversary | D5: =in_cod_year-1 -> 2027 | E5: =in_cod_year+1-1 -> 2028 | F5: =in_cod_year+2-1 -> 2029 | G5: =in_cod_year+3-1 -> 2030 | H5: =in_cod_year+4-1 -> 2031 | I5: =in_cod_year+5-1 -> 2032 | J5: =in_cod_year+6-1 -> 2033 | K5: =in_cod_year+7-1 -> 2034 | L5: =in_cod_year+8-1 -> 2035 | M5: =in_cod_year+9-1 -> 2036 | N5: =in_cod_year+10-1 -> 2037 | O5: =in_cod_year+11-1 -> 2038 | P5: =in_cod_year+12-1 -> 2039 | Q5: =in_cod_year+13-1 -> 2040 | R5: =in_cod_year+14-1 -> 2041 | S5: =in_cod_year+15-1 -> 2042 | T5: =in_cod_year+16-1 -> 2043 | U5: =in_cod_year+17-1 -> 2044 | V5: =in_cod_year+18-1 -> 2045 | W5: =in_cod_year+19-1 -> 2046 | X5: =in_cod_year+20-1 -> 2047 | Y5: =in_cod_year+21-1 -> 2048 | Z5: =in_cod_year+22-1 -> 2049 | AA5: =in_cod_year+23-1 -> 2050 | AB5: =in_cod_year+24-1 -> 2051 | AC5: =in_cod_year+25-1 -> 2052
A7: Energy
A8: Module output factor | B8: x | E8: =(1-in_deg_y1)-in_deg_annual*(1-1) -> 0.99 | F8: =(1-in_deg_y1)-in_deg_annual*(2-1) -> 0.986 | G8: =(1-in_deg_y1)-in_deg_annual*(3-1) -> 0.982 | H8: =(1-in_deg_y1)-in_deg_annual*(4-1) -> 0.978 | I8: =(1-in_deg_y1)-in_deg_annual*(5-1) -> 0.974 | J8: =(1-in_deg_y1)-in_deg_annual*(6-1) -> 0.97 | K8: =(1-in_deg_y1)-in_deg_annual*(7-1) -> 0.966 | L8: =(1-in_deg_y1)-in_deg_annual*(8-1) -> 0.962 | M8: =(1-in_deg_y1)-in_deg_annual*(9-1) -> 0.958 | N8: =(1-in_deg_y1)-in_deg_annual*(10-1) -> 0.954 | O8: =(1-in_deg_y1)-in_deg_annual*(11-1) -> 0.95 | P8: =(1-in_deg_y1)-in_deg_annual*(12-1) -> 0.946 | Q8: =(1-in_deg_y1)-in_deg_annual*(13-1) -> 0.942 | R8: =(1-in_deg_y1)-in_deg_annual*(14-1) -> 0.938 | S8: =(1-in_deg_y1)-in_deg_annual*(15-1) -> 0.934 | T8: =(1-in_deg_y1)-in_deg_annual*(16-1) -> 0.93 | U8: =(1-in_deg_y1)-in_deg_annual*(17-1) -> 0.926 | V8: =(1-in_deg_y1)-in_deg_annual*(18-1) -> 0.922 | W8: =(1-in_deg_y1)-in_deg_annual*(19-1) -> 0.918 | X8: =(1-in_deg_y1)-in_deg_annual*(20-1) -> 0.914 | Y8: =(1-in_deg_y1)-in_deg_annual*(21-1) -> 0.91 | Z8: =(1-in_deg_y1)-in_deg_annual*(22-1) -> 0.906 | AA8: =(1-in_deg_y1)-in_deg_annual*(23-1) -> 0.902 | AB8: =(1-in_deg_y1)-in_deg_annual*(24-1) -> 0.898 | AC8: =(1-in_deg_y1)-in_deg_annual*(25-1) -> 0.894
A9: PV energy available | B9: MWh | E9: =in_mwp*1000*in_pvgis_yield*in_yield_mult*(1-in_clip_loss)*in_availability*E8/1000 -> 96773.978 | F9: =in_mwp*1000*in_pvgis_yield*in_yield_mult*(1-in_clip_loss)*in_availability*F8/1000 -> 96382.972 | G9: =in_mwp*1000*in_pvgis_yield*in_yield_mult*(1-in_clip_loss)*in_availability*G8/1000 -> 95991.966 | H9: =in_mwp*1000*in_pvgis_yield*in_yield_mult*(1-in_clip_loss)*in_availability*H8/1000 -> 95600.96 | I9: =in_mwp*1000*in_pvgis_yield*in_yield_mult*(1-in_clip_loss)*in_availability*I8/1000 -> 95209.954 | J9: =in_mwp*1000*in_pvgis_yield*in_yield_mult*(1-in_clip_loss)*in_availability*J8/1000 -> 94818.948 | K9: =in_mwp*1000*in_pvgis_yield*in_yield_mult*(1-in_clip_loss)*in_availability*K8/1000 -> 94427.942 | L9: =in_mwp*1000*in_pvgis_yield*in_yield_mult*(1-in_clip_loss)*in_availability*L8/1000 -> 94036.936 | ... AC9: =in_mwp*1000*in_pvgis_yield*in_yield_mult*(1-in_clip_loss)*in_availability*AC8/1000 -> 87389.835
A10: BESS capacity factor | B10: x | E10: =IF(1<in_bess_aug_yr,(1-in_bess_fade)^(1-1),(1-in_bess_fade)^(1-in_bess_aug_yr)) -> 1 | F10: =IF(2<in_bess_aug_yr,(1-in_bess_fade)^(2-1),(1-in_bess_fade)^(2-in_bess_aug_yr)) -> 0.98 | G10: =IF(3<in_bess_aug_yr,(1-in_bess_fade)^(3-1),(1-in_bess_fade)^(3-in_bess_aug_yr)) -> 0.9604 | H10: =IF(4<in_bess_aug_yr,(1-in_bess_fade)^(4-1),(1-in_bess_fade)^(4-in_bess_aug_yr)) -> 0.941192 | I10: =IF(5<in_bess_aug_yr,(1-in_bess_fade)^(5-1),(1-in_bess_fade)^(5-in_bess_aug_yr)) -> 0.92236816 | J10: =IF(6<in_bess_aug_yr,(1-in_bess_fade)^(6-1),(1-in_bess_fade)^(6-in_bess_aug_yr)) -> 0.9039208 | K10: =IF(7<in_bess_aug_yr,(1-in_bess_fade)^(7-1),(1-in_bess_fade)^(7-in_bess_aug_yr)) -> 0.88584238 | L10: =IF(8<in_bess_aug_yr,(1-in_bess_fade)^(8-1),(1-in_bess_fade)^(8-in_bess_aug_yr)) -> 0.86812553 | M10: =IF(9<in_bess_aug_yr,(1-in_bess_fade)^(9-1),(1-in_bess_fade)^(9-in_bess_aug_yr)) -> 0.85076302 | N10: =IF(10<in_bess_aug_yr,(1-in_bess_fade)^(10-1),(1-in_bess_fade)^(10-in_bess_aug_yr)) -> 0.83374776 | O10: =IF(11<in_bess_aug_yr,(1-in_bess_fade)^(11-1),(1-in_bess_fade)^(11-in_bess_aug_yr)) -> 0.81707281 | P10: =IF(12<in_bess_aug_yr,(1-in_bess_fade)^(12-1),(1-in_bess_fade)^(12-in_bess_aug_yr)) -> 1 | Q10: =IF(13<in_bess_aug_yr,(1-in_bess_fade)^(13-1),(1-in_bess_fade)^(13-in_bess_aug_yr)) -> 0.98 | R10: =IF(14<in_bess_aug_yr,(1-in_bess_fade)^(14-1),(1-in_bess_fade)^(14-in_bess_aug_yr)) -> 0.9604 | S10: =IF(15<in_bess_aug_yr,(1-in_bess_fade)^(15-1),(1-in_bess_fade)^(15-in_bess_aug_yr)) -> 0.941192 | T10: =IF(16<in_bess_aug_yr,(1-in_bess_fade)^(16-1),(1-in_bess_fade)^(16-in_bess_aug_yr)) -> 0.92236816 | U10: =IF(17<in_bess_aug_yr,(1-in_bess_fade)^(17-1),(1-in_bess_fade)^(17-in_bess_aug_yr)) -> 0.9039208 | V10: =IF(18<in_bess_aug_yr,(1-in_bess_fade)^(18-1),(1-in_bess_fade)^(18-in_bess_aug_yr)) -> 0.88584238 | W10: =IF(19<in_bess_aug_yr,(1-in_bess_fade)^(19-1),(1-in_bess_fade)^(19-in_bess_aug_yr)) -> 0.86812553 | X10: =IF(20<in_bess_aug_yr,(1-in_bess_fade)^(20-1),(1-in_bess_fade)^(20-in_bess_aug_yr)) -> 0.85076302 | Y10: =IF(21<in_bess_aug_yr,(1-in_bess_fade)^(21-1),(1-in_bess_fade)^(21-in_bess_aug_yr)) -> 0.83374776 | Z10: =IF(22<in_bess_aug_yr,(1-in_bess_fade)^(22-1),(1-in_bess_fade)^(22-in_bess_aug_yr)) -> 0.81707281 | AA10: =IF(23<in_bess_aug_yr,(1-in_bess_fade)^(23-1),(1-in_bess_fade)^(23-in_bess_aug_yr)) -> 0.80073135 | AB10: =IF(24<in_bess_aug_yr,(1-in_bess_fade)^(24-1),(1-in_bess_fade)^(24-in_bess_aug_yr)) -> 0.78471672 | AC10: =IF(25<in_bess_aug_yr,(1-in_bess_fade)^(25-1),(1-in_bess_fade)^(25-in_bess_aug_yr)) -> 0.76902239
A11: Energy routed to BESS | B11: MWh | E11: =MIN(in_bess_on*in_bess_charge_yr1*E10,E9) -> 0 | F11: =MIN(in_bess_on*in_bess_charge_yr1*F10,F9) -> 0 | G11: =MIN(in_bess_on*in_bess_charge_yr1*G10,G9) -> 0 | H11: =MIN(in_bess_on*in_bess_charge_yr1*H10,H9) -> 0 | I11: =MIN(in_bess_on*in_bess_charge_yr1*I10,I9) -> 0 | J11: =MIN(in_bess_on*in_bess_charge_yr1*J10,J9) -> 0 | K11: =MIN(in_bess_on*in_bess_charge_yr1*K10,K9) -> 0 | L11: =MIN(in_bess_on*in_bess_charge_yr1*L10,L9) -> 0 | ... AC11: =MIN(in_bess_on*in_bess_charge_yr1*AC10,AC9) -> 0
A12: BESS evening discharge | B12: MWh | E12: =E11*in_bess_dis_ratio -> 0 | F12: =F11*in_bess_dis_ratio -> 0 | G12: =G11*in_bess_dis_ratio -> 0 | H12: =H11*in_bess_dis_ratio -> 0 | I12: =I11*in_bess_dis_ratio -> 0 | J12: =J11*in_bess_dis_ratio -> 0 | K12: =K11*in_bess_dis_ratio -> 0 | L12: =L11*in_bess_dis_ratio -> 0 | ... AC12: =AC11*in_bess_dis_ratio -> 0
A13: Daytime energy sold | B13: MWh | E13: =E9-E11 -> 96773.978 | F13: =F9-F11 -> 96382.972 | G13: =G9-G11 -> 95991.966 | H13: =H9-H11 -> 95600.96 | I13: =I9-I11 -> 95209.954 | J13: =J9-J11 -> 94818.948 | K13: =K9-K11 -> 94427.942 | L13: =L9-L11 -> 94036.936 | ... AC13: =AC9-AC11 -> 87389.835
A14: Total energy delivered | B14: MWh | E14: =E13+E12 -> 96773.978 | F14: =F13+F12 -> 96382.972 | G14: =G13+G12 -> 95991.966 | H14: =H13+H12 -> 95600.96 | I14: =I13+I12 -> 95209.954 | J14: =J13+J12 -> 94818.948 | K14: =K13+K12 -> 94427.942 | L14: =L13+L12 -> 94036.936 | ... AC14: =AC13+AC12 -> 87389.835
A16: Revenue
A17: PPA indexation factor | B17: x | E17: =(1+in_ppa_esc)^(1-1) -> 1 | F17: =(1+in_ppa_esc)^(2-1) -> 1.01 | G17: =(1+in_ppa_esc)^(3-1) -> 1.0201 | H17: =(1+in_ppa_esc)^(4-1) -> 1.030301 | I17: =(1+in_ppa_esc)^(5-1) -> 1.040604 | J17: =(1+in_ppa_esc)^(6-1) -> 1.0510101 | K17: =(1+in_ppa_esc)^(7-1) -> 1.0615202 | L17: =(1+in_ppa_esc)^(8-1) -> 1.0721354 | M17: =(1+in_ppa_esc)^(9-1) -> 1.0828567 | N17: =(1+in_ppa_esc)^(10-1) -> 1.0936853 | O17: =(1+in_ppa_esc)^(11-1) -> 1.1046221 | P17: =(1+in_ppa_esc)^(12-1) -> 1.1156683 | Q17: =(1+in_ppa_esc)^(13-1) -> 1.126825 | R17: =(1+in_ppa_esc)^(14-1) -> 1.1380933 | S17: =(1+in_ppa_esc)^(15-1) -> 1.1494742 | T17: =(1+in_ppa_esc)^(16-1) -> 1.160969 | U17: =(1+in_ppa_esc)^(17-1) -> 1.1725786 | V17: =(1+in_ppa_esc)^(18-1) -> 1.1843044 | W17: =(1+in_ppa_esc)^(19-1) -> 1.1961475 | X17: =(1+in_ppa_esc)^(20-1) -> 1.208109 | Y17: =(1+in_ppa_esc)^(21-1) -> 1.22019 | Z17: =(1+in_ppa_esc)^(22-1) -> 1.2323919 | AA17: =(1+in_ppa_esc)^(23-1) -> 1.2447159 | AB17: =(1+in_ppa_esc)^(24-1) -> 1.257163 | AC17: =(1+in_ppa_esc)^(25-1) -> 1.2697346
A18: Daytime tariff | B18: USD/kWh | E18: =in_ppa_day*E17 -> 0.1 | F18: =in_ppa_day*F17 -> 0.101 | G18: =in_ppa_day*G17 -> 0.10201 | H18: =in_ppa_day*H17 -> 0.1030301 | I18: =in_ppa_day*I17 -> 0.1040604 | J18: =in_ppa_day*J17 -> 0.10510101 | K18: =in_ppa_day*K17 -> 0.10615202 | L18: =in_ppa_day*L17 -> 0.10721354 | ... AC18: =in_ppa_day*AC17 -> 0.12697346
A19: Evening tariff | B19: USD/kWh | E19: =in_ppa_evening*E17 -> 0.16 | F19: =in_ppa_evening*F17 -> 0.1616 | G19: =in_ppa_evening*G17 -> 0.163216 | H19: =in_ppa_evening*H17 -> 0.16484816 | I19: =in_ppa_evening*I17 -> 0.16649664 | J19: =in_ppa_evening*J17 -> 0.16816161 | K19: =in_ppa_evening*K17 -> 0.16984322 | L19: =in_ppa_evening*L17 -> 0.17154166 | ... AC19: =in_ppa_evening*AC17 -> 0.20315754
A20: Billed revenue | B20: USD | E20: =(E13*E18+E12*E19)*1000 -> 9677397.8 | F20: =(F13*F18+F12*F19)*1000 -> 9734680.2 | G20: =(G13*G18+G12*G19)*1000 -> 9792140.5 | H20: =(H13*H18+H12*H19)*1000 -> 9849776.5 | I20: =(I13*I18+I12*I19)*1000 -> 9907586 | J20: =(J13*J18+J12*J19)*1000 -> 9965566.8 | K20: =(K13*K18+K12*K19)*1000 -> 10023716 | L20: =(L13*L18+L12*L19)*1000 -> 10082032 | ... AC20: =(AC13*AC18+AC12*AC19)*1000 -> 11096190
A21: Revenue after collection and FX loss | B21: USD | E21: =E20*in_collection*(1-in_fx_haircut) -> 9105463.6 | F21: =F20*in_collection*(1-in_fx_haircut) -> 9159360.6 | G21: =G20*in_collection*(1-in_fx_haircut) -> 9213425 | H21: =H20*in_collection*(1-in_fx_haircut) -> 9267654.7 | I21: =I20*in_collection*(1-in_fx_haircut) -> 9322047.7 | J21: =J20*in_collection*(1-in_fx_haircut) -> 9376601.8 | K21: =K20*in_collection*(1-in_fx_haircut) -> 9431314.7 | L21: =L20*in_collection*(1-in_fx_haircut) -> 9486184.3 | ... AC21: =AC20*in_collection*(1-in_fx_haircut) -> 10440405
A23: Operating costs
A24: Opex escalation factor | B24: x | E24: =(1+in_opex_esc)^(1-1) -> 1 | F24: =(1+in_opex_esc)^(2-1) -> 1.025 | G24: =(1+in_opex_esc)^(3-1) -> 1.050625 | H24: =(1+in_opex_esc)^(4-1) -> 1.0768906 | I24: =(1+in_opex_esc)^(5-1) -> 1.1038129 | J24: =(1+in_opex_esc)^(6-1) -> 1.1314082 | K24: =(1+in_opex_esc)^(7-1) -> 1.1596934 | L24: =(1+in_opex_esc)^(8-1) -> 1.1886858 | M24: =(1+in_opex_esc)^(9-1) -> 1.2184029 | N24: =(1+in_opex_esc)^(10-1) -> 1.248863 | O24: =(1+in_opex_esc)^(11-1) -> 1.2800845 | P24: =(1+in_opex_esc)^(12-1) -> 1.3120867 | Q24: =(1+in_opex_esc)^(13-1) -> 1.3448888 | R24: =(1+in_opex_esc)^(14-1) -> 1.378511 | S24: =(1+in_opex_esc)^(15-1) -> 1.4129738 | T24: =(1+in_opex_esc)^(16-1) -> 1.4482982 | U24: =(1+in_opex_esc)^(17-1) -> 1.4845056 | V24: =(1+in_opex_esc)^(18-1) -> 1.5216183 | W24: =(1+in_opex_esc)^(19-1) -> 1.5596587 | X24: =(1+in_opex_esc)^(20-1) -> 1.5986502 | Y24: =(1+in_opex_esc)^(21-1) -> 1.6386164 | Z24: =(1+in_opex_esc)^(22-1) -> 1.6795819 | AA24: =(1+in_opex_esc)^(23-1) -> 1.7215714 | AB24: =(1+in_opex_esc)^(24-1) -> 1.7646107 | AC24: =(1+in_opex_esc)^(25-1) -> 1.8087259
A25: O&M contract | B25: USD | E25: =in_om_per_kwp*in_mwp*1000*E24*in_opex_mult -> 540000 | F25: =in_om_per_kwp*in_mwp*1000*F24*in_opex_mult -> 553500 | G25: =in_om_per_kwp*in_mwp*1000*G24*in_opex_mult -> 567337.5 | H25: =in_om_per_kwp*in_mwp*1000*H24*in_opex_mult -> 581520.94 | I25: =in_om_per_kwp*in_mwp*1000*I24*in_opex_mult -> 596058.96 | J25: =in_om_per_kwp*in_mwp*1000*J24*in_opex_mult -> 610960.43 | K25: =in_om_per_kwp*in_mwp*1000*K24*in_opex_mult -> 626234.45 | L25: =in_om_per_kwp*in_mwp*1000*L24*in_opex_mult -> 641890.31 | ... AC25: =in_om_per_kwp*in_mwp*1000*AC24*in_opex_mult -> 976712.01
A26: Insurance | B26: USD | E26: =in_insurance_pct*x_capex*E24*in_opex_mult -> 193465.66 | F26: =in_insurance_pct*x_capex*F24*in_opex_mult -> 198302.3 | G26: =in_insurance_pct*x_capex*G24*in_opex_mult -> 203259.85 | H26: =in_insurance_pct*x_capex*H24*in_opex_mult -> 208341.35 | I26: =in_insurance_pct*x_capex*I24*in_opex_mult -> 213549.88 | J26: =in_insurance_pct*x_capex*J24*in_opex_mult -> 218888.63 | K26: =in_insurance_pct*x_capex*K24*in_opex_mult -> 224360.85 | L26: =in_insurance_pct*x_capex*L24*in_opex_mult -> 229969.87 | ... AC26: =in_insurance_pct*x_capex*AC24*in_opex_mult -> 349926.35
A27: Political risk insurance | B27: USD | E27: =in_pri_pct_debt*x_debt*E24*in_opex_mult -> 161360.89 | F27: =in_pri_pct_debt*x_debt*F24*in_opex_mult -> 165394.91 | G27: =in_pri_pct_debt*x_debt*G24*in_opex_mult -> 169529.78 | H27: =in_pri_pct_debt*x_debt*H24*in_opex_mult -> 173768.03 | I27: =in_pri_pct_debt*x_debt*I24*in_opex_mult -> 178112.23 | J27: =in_pri_pct_debt*x_debt*J24*in_opex_mult -> 182565.04 | K27: =in_pri_pct_debt*x_debt*K24*in_opex_mult -> 187129.16 | L27: =in_pri_pct_debt*x_debt*L24*in_opex_mult -> 191807.39 | ... AC27: =in_pri_pct_debt*x_debt*AC24*in_opex_mult -> 291857.63
A28: Security | B28: USD | E28: =in_security_fix*E24*in_opex_mult -> 250000 | F28: =in_security_fix*F24*in_opex_mult -> 256250 | G28: =in_security_fix*G24*in_opex_mult -> 262656.25 | H28: =in_security_fix*H24*in_opex_mult -> 269222.66 | I28: =in_security_fix*I24*in_opex_mult -> 275953.22 | J28: =in_security_fix*J24*in_opex_mult -> 282852.05 | K28: =in_security_fix*K24*in_opex_mult -> 289923.35 | L28: =in_security_fix*L24*in_opex_mult -> 297171.44 | ... AC28: =in_security_fix*AC24*in_opex_mult -> 452181.49
A29: Land lease | B29: USD | E29: =in_land_lease_per_ha*in_land_ha_per_mwp*in_mwp*E24*in_opex_mult -> 46800 | F29: =in_land_lease_per_ha*in_land_ha_per_mwp*in_mwp*F24*in_opex_mult -> 47970 | G29: =in_land_lease_per_ha*in_land_ha_per_mwp*in_mwp*G24*in_opex_mult -> 49169.25 | H29: =in_land_lease_per_ha*in_land_ha_per_mwp*in_mwp*H24*in_opex_mult -> 50398.481 | I29: =in_land_lease_per_ha*in_land_ha_per_mwp*in_mwp*I24*in_opex_mult -> 51658.443 | J29: =in_land_lease_per_ha*in_land_ha_per_mwp*in_mwp*J24*in_opex_mult -> 52949.904 | K29: =in_land_lease_per_ha*in_land_ha_per_mwp*in_mwp*K24*in_opex_mult -> 54273.652 | L29: =in_land_lease_per_ha*in_land_ha_per_mwp*in_mwp*L24*in_opex_mult -> 55630.493 | ... AC29: =in_land_lease_per_ha*in_land_ha_per_mwp*in_mwp*AC24*in_opex_mult -> 84648.374
A30: SPV administration, billing, metering | B30: USD | E30: =in_admin_fix*E24*in_opex_mult -> 300000 | F30: =in_admin_fix*F24*in_opex_mult -> 307500 | G30: =in_admin_fix*G24*in_opex_mult -> 315187.5 | H30: =in_admin_fix*H24*in_opex_mult -> 323067.19 | I30: =in_admin_fix*I24*in_opex_mult -> 331143.87 | J30: =in_admin_fix*J24*in_opex_mult -> 339422.46 | K30: =in_admin_fix*K24*in_opex_mult -> 347908.03 | L30: =in_admin_fix*L24*in_opex_mult -> 356605.73 | ... AC30: =in_admin_fix*AC24*in_opex_mult -> 542617.78
A31: BESS O&M | B31: USD | E31: =in_bess_om_pct*x_capex_bess*E24*in_opex_mult -> 0 | F31: =in_bess_om_pct*x_capex_bess*F24*in_opex_mult -> 0 | G31: =in_bess_om_pct*x_capex_bess*G24*in_opex_mult -> 0 | H31: =in_bess_om_pct*x_capex_bess*H24*in_opex_mult -> 0 | I31: =in_bess_om_pct*x_capex_bess*I24*in_opex_mult -> 0 | J31: =in_bess_om_pct*x_capex_bess*J24*in_opex_mult -> 0 | K31: =in_bess_om_pct*x_capex_bess*K24*in_opex_mult -> 0 | L31: =in_bess_om_pct*x_capex_bess*L24*in_opex_mult -> 0 | ... AC31: =in_bess_om_pct*x_capex_bess*AC24*in_opex_mult -> 0
A32: Network use and metering charge | B32: USD | E32: =in_wheeling*E14*1000*E24*in_opex_mult -> 483869.89 | F32: =in_wheeling*F14*1000*F24*in_opex_mult -> 493962.73 | G32: =in_wheeling*G14*1000*G24*in_opex_mult -> 504257.8 | H32: =in_wheeling*H14*1000*H24*in_opex_mult -> 514758.89 | I32: =in_wheeling*I14*1000*I24*in_opex_mult -> 525469.87 | J32: =in_wheeling*J14*1000*J24*in_opex_mult -> 536394.68 | K32: =in_wheeling*K14*1000*K24*in_opex_mult -> 547537.32 | L32: =in_wheeling*L14*1000*L24*in_opex_mult -> 558901.83 | ... AC32: =in_wheeling*AC14*1000*AC24*in_opex_mult -> 790321.31
A33: Total opex | B33: USD | E33: =SUM(E25:E32) -> 1975496.4 | F33: =SUM(F25:F32) -> 2022879.9 | G33: =SUM(G25:G32) -> 2071397.9 | H33: =SUM(H25:H32) -> 2121077.5 | I33: =SUM(I25:I32) -> 2171946.5 | J33: =SUM(J25:J32) -> 2224033.2 | K33: =SUM(K25:K32) -> 2277366.8 | L33: =SUM(L25:L32) -> 2331977.1 | ... AC33: =SUM(AC25:AC32) -> 3488265
A34: EBITDA | B34: USD | E34: =E21-E33 -> 7129967.2 | F34: =F21-F33 -> 7136480.7 | G34: =G21-G33 -> 7142027 | H34: =H21-H33 -> 7146577.2 | I34: =I21-I33 -> 7150101.2 | J34: =J21-J33 -> 7152568.6 | K34: =K21-K33 -> 7153947.9 | L34: =L21-L33 -> 7154207.2 | ... AC34: =AC21-AC33 -> 6952140.3
A35: Replacement capex (inverters, BESS augmentation) | B35: USD | E35: =IF(1=in_inverter_repl_yr,in_inverter_repl_cost*in_mwp*1000000,0)+IF(1=in_bess_aug_yr,in_bess_on*in_bess_aug_cost,0) -> 0 | F35: =IF(2=in_inverter_repl_yr,in_inverter_repl_cost*in_mwp*1000000,0)+IF(2=in_bess_aug_yr,in_bess_on*in_bess_aug_cost,0) -> 0 | G35: =IF(3=in_inverter_repl_yr,in_inverter_repl_cost*in_mwp*1000000,0)+IF(3=in_bess_aug_yr,in_bess_on*in_bess_aug_cost,0) -> 0 | H35: =IF(4=in_inverter_repl_yr,in_inverter_repl_cost*in_mwp*1000000,0)+IF(4=in_bess_aug_yr,in_bess_on*in_bess_aug_cost,0) -> 0 | I35: =IF(5=in_inverter_repl_yr,in_inverter_repl_cost*in_mwp*1000000,0)+IF(5=in_bess_aug_yr,in_bess_on*in_bess_aug_cost,0) -> 0 | J35: =IF(6=in_inverter_repl_yr,in_inverter_repl_cost*in_mwp*1000000,0)+IF(6=in_bess_aug_yr,in_bess_on*in_bess_aug_cost,0) -> 0 | K35: =IF(7=in_inverter_repl_yr,in_inverter_repl_cost*in_mwp*1000000,0)+IF(7=in_bess_aug_yr,in_bess_on*in_bess_aug_cost,0) -> 0 | L35: =IF(8=in_inverter_repl_yr,in_inverter_repl_cost*in_mwp*1000000,0)+IF(8=in_bess_aug_yr,in_bess_on*in_bess_aug_cost,0) -> 0 | M35: =IF(9=in_inverter_repl_yr,in_inverter_repl_cost*in_mwp*1000000,0)+IF(9=in_bess_aug_yr,in_bess_on*in_bess_aug_cost,0) -> 0 | N35: =IF(10=in_inverter_repl_yr,in_inverter_repl_cost*in_mwp*1000000,0)+IF(10=in_bess_aug_yr,in_bess_on*in_bess_aug_cost,0) -> 0 | O35: =IF(11=in_inverter_repl_yr,in_inverter_repl_cost*in_mwp*1000000,0)+IF(11=in_bess_aug_yr,in_bess_on*in_bess_aug_cost,0) -> 0 | P35: =IF(12=in_inverter_repl_yr,in_inverter_repl_cost*in_mwp*1000000,0)+IF(12=in_bess_aug_yr,in_bess_on*in_bess_aug_cost,0) -> 0 | Q35: =IF(13=in_inverter_repl_yr,in_inverter_repl_cost*in_mwp*1000000,0)+IF(13=in_bess_aug_yr,in_bess_on*in_bess_aug_cost,0) -> 1500000 | R35: =IF(14=in_inverter_repl_yr,in_inverter_repl_cost*in_mwp*1000000,0)+IF(14=in_bess_aug_yr,in_bess_on*in_bess_aug_cost,0) -> 0 | S35: =IF(15=in_inverter_repl_yr,in_inverter_repl_cost*in_mwp*1000000,0)+IF(15=in_bess_aug_yr,in_bess_on*in_bess_aug_cost,0) -> 0 | T35: =IF(16=in_inverter_repl_yr,in_inverter_repl_cost*in_mwp*1000000,0)+IF(16=in_bess_aug_yr,in_bess_on*in_bess_aug_cost,0) -> 0 | U35: =IF(17=in_inverter_repl_yr,in_inverter_repl_cost*in_mwp*1000000,0)+IF(17=in_bess_aug_yr,in_bess_on*in_bess_aug_cost,0) -> 0 | V35: =IF(18=in_inverter_repl_yr,in_inverter_repl_cost*in_mwp*1000000,0)+IF(18=in_bess_aug_yr,in_bess_on*in_bess_aug_cost,0) -> 0 | W35: =IF(19=in_inverter_repl_yr,in_inverter_repl_cost*in_mwp*1000000,0)+IF(19=in_bess_aug_yr,in_bess_on*in_bess_aug_cost,0) -> 0 | X35: =IF(20=in_inverter_repl_yr,in_inverter_repl_cost*in_mwp*1000000,0)+IF(20=in_bess_aug_yr,in_bess_on*in_bess_aug_cost,0) -> 0 | Y35: =IF(21=in_inverter_repl_yr,in_inverter_repl_cost*in_mwp*1000000,0)+IF(21=in_bess_aug_yr,in_bess_on*in_bess_aug_cost,0) -> 0 | Z35: =IF(22=in_inverter_repl_yr,in_inverter_repl_cost*in_mwp*1000000,0)+IF(22=in_bess_aug_yr,in_bess_on*in_bess_aug_cost,0) -> 0 | AA35: =IF(23=in_inverter_repl_yr,in_inverter_repl_cost*in_mwp*1000000,0)+IF(23=in_bess_aug_yr,in_bess_on*in_bess_aug_cost,0) -> 0 | AB35: =IF(24=in_inverter_repl_yr,in_inverter_repl_cost*in_mwp*1000000,0)+IF(24=in_bess_aug_yr,in_bess_on*in_bess_aug_cost,0) -> 0 | AC35: =IF(25=in_inverter_repl_yr,in_inverter_repl_cost*in_mwp*1000000,0)+IF(25=in_bess_aug_yr,in_bess_on*in_bess_aug_cost,0) -> 0
A37: Senior debt
A38: Opening balance | B38: USD | E38: =x_debt -> 20170111 | F38: =E42 -> 19204547 | G38: =F42 -> 18146191 | H38: =G42 -> 16986128 | I38: =H42 -> 15714582 | J38: =I42 -> 14320841 | K38: =J42 -> 12793162 | L38: =K42 -> 11118672 | M38: =L42 -> 9283264 | ... AC38: =AB42 -> 0
A39: Interest | B39: USD | E39: =IF(1<=in_tenor,E38*x_kd,0) -> 1938347.7 | F39: =IF(2<=in_tenor,F38*x_kd,0) -> 1845556.9 | G39: =IF(3<=in_tenor,G38*x_kd,0) -> 1743849 | H39: =IF(4<=in_tenor,H38*x_kd,0) -> 1632366.9 | I39: =IF(5<=in_tenor,I38*x_kd,0) -> 1510171.3 | J39: =IF(6<=in_tenor,J38*x_kd,0) -> 1376232.8 | K39: =IF(7<=in_tenor,K38*x_kd,0) -> 1229422.8 | L39: =IF(8<=in_tenor,L38*x_kd,0) -> 1068504.4 | M39: =IF(9<=in_tenor,M38*x_kd,0) -> 892121.68 | N39: =IF(10<=in_tenor,N38*x_kd,0) -> 698788.59 | O39: =IF(11<=in_tenor,O38*x_kd,0) -> 486876.19 | P39: =IF(12<=in_tenor,P38*x_kd,0) -> 254599.01 | Q39: =IF(13<=in_tenor,Q38*x_kd,0) -> 0 | R39: =IF(14<=in_tenor,R38*x_kd,0) -> 0 | S39: =IF(15<=in_tenor,S38*x_kd,0) -> 0 | T39: =IF(16<=in_tenor,T38*x_kd,0) -> 0 | U39: =IF(17<=in_tenor,U38*x_kd,0) -> 0 | V39: =IF(18<=in_tenor,V38*x_kd,0) -> 0 | W39: =IF(19<=in_tenor,W38*x_kd,0) -> 0 | X39: =IF(20<=in_tenor,X38*x_kd,0) -> 0 | Y39: =IF(21<=in_tenor,Y38*x_kd,0) -> 0 | Z39: =IF(22<=in_tenor,Z38*x_kd,0) -> 0 | AA39: =IF(23<=in_tenor,AA38*x_kd,0) -> 0 | AB39: =IF(24<=in_tenor,AB38*x_kd,0) -> 0 | AC39: =IF(25<=in_tenor,AC38*x_kd,0) -> 0
A40: Debt service (annuity) | B40: USD | E40: =IF(1<=in_tenor,x_pmt,0) -> 2903912.4 | F40: =IF(2<=in_tenor,x_pmt,0) -> 2903912.4 | G40: =IF(3<=in_tenor,x_pmt,0) -> 2903912.4 | H40: =IF(4<=in_tenor,x_pmt,0) -> 2903912.4 | I40: =IF(5<=in_tenor,x_pmt,0) -> 2903912.4 | J40: =IF(6<=in_tenor,x_pmt,0) -> 2903912.4 | K40: =IF(7<=in_tenor,x_pmt,0) -> 2903912.4 | L40: =IF(8<=in_tenor,x_pmt,0) -> 2903912.4 | M40: =IF(9<=in_tenor,x_pmt,0) -> 2903912.4 | N40: =IF(10<=in_tenor,x_pmt,0) -> 2903912.4 | O40: =IF(11<=in_tenor,x_pmt,0) -> 2903912.4 | P40: =IF(12<=in_tenor,x_pmt,0) -> 2903912.4 | Q40: =IF(13<=in_tenor,x_pmt,0) -> 0 | R40: =IF(14<=in_tenor,x_pmt,0) -> 0 | S40: =IF(15<=in_tenor,x_pmt,0) -> 0 | T40: =IF(16<=in_tenor,x_pmt,0) -> 0 | U40: =IF(17<=in_tenor,x_pmt,0) -> 0 | V40: =IF(18<=in_tenor,x_pmt,0) -> 0 | W40: =IF(19<=in_tenor,x_pmt,0) -> 0 | X40: =IF(20<=in_tenor,x_pmt,0) -> 0 | Y40: =IF(21<=in_tenor,x_pmt,0) -> 0 | Z40: =IF(22<=in_tenor,x_pmt,0) -> 0 | AA40: =IF(23<=in_tenor,x_pmt,0) -> 0 | AB40: =IF(24<=in_tenor,x_pmt,0) -> 0 | AC40: =IF(25<=in_tenor,x_pmt,0) -> 0
A41: Principal repayment | B41: USD | E41: =E40-E39 -> 965564.69 | F41: =F40-F39 -> 1058355.5 | G41: =G40-G39 -> 1160063.4 | H41: =H40-H39 -> 1271545.5 | I41: =I40-I39 -> 1393741 | J41: =J40-J39 -> 1527679.5 | K41: =K40-K39 -> 1674489.6 | L41: =L40-L39 -> 1835408 | ... AC41: =AC40-AC39 -> 0
A42: Closing balance | B42: USD | E42: =E38-E41 -> 19204547 | F42: =F38-F41 -> 18146191 | G42: =G38-G41 -> 16986128 | H42: =H38-H41 -> 15714582 | I42: =I38-I41 -> 14320841 | J42: =J38-J41 -> 12793162 | K42: =K38-K41 -> 11118672 | L42: =L38-L41 -> 9283264 | ... AC42: =AC38-AC41 -> 0
A44: Tax
A45: Depreciation (funding cost, straight line) | B45: USD | E45: =IF(1<=in_dep_years,x_funding/in_dep_years,0) -> 1680842.6 | F45: =IF(2<=in_dep_years,x_funding/in_dep_years,0) -> 1680842.6 | G45: =IF(3<=in_dep_years,x_funding/in_dep_years,0) -> 1680842.6 | H45: =IF(4<=in_dep_years,x_funding/in_dep_years,0) -> 1680842.6 | I45: =IF(5<=in_dep_years,x_funding/in_dep_years,0) -> 1680842.6 | J45: =IF(6<=in_dep_years,x_funding/in_dep_years,0) -> 1680842.6 | K45: =IF(7<=in_dep_years,x_funding/in_dep_years,0) -> 1680842.6 | L45: =IF(8<=in_dep_years,x_funding/in_dep_years,0) -> 1680842.6 | M45: =IF(9<=in_dep_years,x_funding/in_dep_years,0) -> 1680842.6 | N45: =IF(10<=in_dep_years,x_funding/in_dep_years,0) -> 1680842.6 | O45: =IF(11<=in_dep_years,x_funding/in_dep_years,0) -> 1680842.6 | P45: =IF(12<=in_dep_years,x_funding/in_dep_years,0) -> 1680842.6 | Q45: =IF(13<=in_dep_years,x_funding/in_dep_years,0) -> 1680842.6 | R45: =IF(14<=in_dep_years,x_funding/in_dep_years,0) -> 1680842.6 | S45: =IF(15<=in_dep_years,x_funding/in_dep_years,0) -> 1680842.6 | T45: =IF(16<=in_dep_years,x_funding/in_dep_years,0) -> 1680842.6 | U45: =IF(17<=in_dep_years,x_funding/in_dep_years,0) -> 1680842.6 | V45: =IF(18<=in_dep_years,x_funding/in_dep_years,0) -> 1680842.6 | W45: =IF(19<=in_dep_years,x_funding/in_dep_years,0) -> 1680842.6 | X45: =IF(20<=in_dep_years,x_funding/in_dep_years,0) -> 1680842.6 | Y45: =IF(21<=in_dep_years,x_funding/in_dep_years,0) -> 0 | Z45: =IF(22<=in_dep_years,x_funding/in_dep_years,0) -> 0 | AA45: =IF(23<=in_dep_years,x_funding/in_dep_years,0) -> 0 | AB45: =IF(24<=in_dep_years,x_funding/in_dep_years,0) -> 0 | AC45: =IF(25<=in_dep_years,x_funding/in_dep_years,0) -> 0
A46: Taxable income before losses | B46: USD | E46: =E34-E45-E39-E35 -> 3510776.9 | F46: =F34-F45-F39-F35 -> 3610081.1 | G46: =G34-G45-G39-G35 -> 3717335.5 | H46: =H34-H45-H39-H35 -> 3833367.7 | I46: =I34-I45-I39-I35 -> 3959087.3 | J46: =J34-J45-J39-J35 -> 4095493.1 | K46: =K34-K45-K39-K35 -> 4243682.5 | L46: =L34-L45-L39-L35 -> 4404860.2 | ... AC46: =AC34-AC45-AC39-AC35 -> 6952140.3
...

Sheet Returns
A1: Metric | B1: Value | C1: Unit / note
A2: Cost of equity (CAPM + country risk premium) | B2: =in_ust10+in_beta*in_mature_erp+in_crp_syria -> 0.243455 | C2: 10-yr UST + beta x mature ERP + Syria CRP
A3: WACC (post-tax, relief-period tax rate) | B3: =(1-in_gearing)*x_ke+in_gearing*x_kd*(1-in_cit*(1-in_tax_relief)) -> 0.1536005 | C3: Project discount rate
A4: Project NPV at WACC | B4: =CashFlow!$D$63+NPV(x_wacc,CashFlow!$E$63:$AC$63) -> 9926005.6 | C4: USD
A5: Project IRR | B5: =IRR(CashFlow!$D$63:$AC$63) -> 0.20432152 | C5: Unlevered, after tax
A6: Equity NPV at cost of equity | B6: =CashFlow!$D$60+NPV(x_ke,CashFlow!$E$60:$AC$60) -> 2800480.8 | C6: USD
A7: Equity IRR | B7: =IRR(CashFlow!$D$60:$AC$60) -> 0.28834832 | C7: Levered, after tax
A8: Project payback | B8: =SUM(CashFlow!$E$67:$AC$67) -> 4.8232994 | C8: Years from COD (undiscounted)
A9: Equity payback | B9: =SUM(CashFlow!$E$69:$AC$69) -> 3.6127465 | C9: Years from COD (undiscounted)
A10: LCOE at WACC | B10: =(x_capex+SUM(CashFlow!$E$71:$AC$71))/SUM(CashFlow!$E$72:$AC$72) -> 0.078500576 | C10: USD/kWh, nominal levelised, pre-tax
A11: LCOE at 8% (benchmark discount rate) | B11: =(x_capex+SUM(CashFlow!$E$74:$AC$74))/SUM(CashFlow!$E$75:$AC$75) -> 0.058823993 | C11: USD/kWh
A12: Minimum DSCR | B12: =MIN(CashFlow!$E$59:$P$59) -> 1.9096338 | C12: Over loan tenor
A13: Average DSCR | B13: =AVERAGE(CashFlow!$E$59:$P$59) -> 2.3568506 | C13: Over loan tenor
A14: LLCR | B14: =SUM(CashFlow!$E$76:$AC$76)/x_debt -> 2.341825 | C14: PV of CFADS over loan life / debt
A15: Year-1 energy delivered | B15: =CashFlow!$E$14 -> 96773.978 | C15: MWh
A16: Year-1 revenue | B16: =CashFlow!$E$21 -> 9105463.6 | C16: USD
A17: Year-1 opex | B17: =CashFlow!$E$33 -> 1975496.4 | C17: USD
A18: Year-1 EBITDA | B18: =CashFlow!$E$34 -> 7129967.2 | C18: USD
A19: Lifetime energy delivered | B19: =SUM(CashFlow!$E$14:$AC$14) -> 2302047.7 | C19: MWh
A20: Specific yield year 1 | B20: =CashFlow!$E$14*1000/(in_mwp*1000) -> 1612.8996 | C20: kWh/kWp delivered
A21: Capacity factor year 1 (AC) | B21: =CashFlow!$E$14/(in_mwac*8760) -> 0.22094516 | C21: On 50 MWac

Sheet Market
A1: Comparator | B1: USD/kWh | C1: Basis
A2: Grid tariff, industrial (official FX) | B2: =in_grid_ind_syp/in_fx_official -> 0.13877551 | C2: Decision 687, 17 SYP/kWh / 122.5
A3: Grid tariff, industrial (parallel FX) | B3: =in_grid_ind_syp/in_fx_parallel -> 0.12099644 | C3: 17 SYP/kWh / 140.5
A4: Grid tariff, heavy industry (official FX) | B4: =in_grid_heavy_syp/in_fx_official -> 0.14693878 | C4: 18 SYP/kWh
A5: Diesel self-generation, industrial diesel (official FX) | B5: =in_diesel_ind_syp/in_fx_official*in_genset_sfc+in_genset_nonfuel -> 0.37285714 | C5: 150 SYP/L x 0.28 L/kWh + non-fuel cost
A6: Diesel self-generation, industrial diesel (parallel FX) | B6: =in_diesel_ind_syp/in_fx_parallel*in_genset_sfc+in_genset_nonfuel -> 0.32893238
A7: Diesel self-generation, standard diesel (official FX) | B7: =in_diesel_std_syp/in_fx_official*in_genset_sfc+in_genset_nonfuel -> 0.43 | C7: 175 SYP/L
A8: Proposed PPA tariff, year 1 | B8: =in_ppa_day -> 0.1
A9: PPA discount to grid tariff (official FX) | B9: =1-B8/B2 -> 0.27941176 | C9: share
A10: PPA discount to diesel self-generation | B10: =1-B8/B5 -> 0.73180077 | C10: share
A11: Decision 154 feed-in tariff, solar | B11: =in_fit_154_pv -> 0.04 | C11: State purchase, 2-10 MW projects
A12: Official / parallel FX gap | B12: =1-in_fx_official/in_fx_parallel -> 0.12811388 | C12: share
A13: CO2 from diesel self-generation | B13: =in_genset_sfc*in_dfi_ef_diesel -> 0.75516 | C13: t CO2 per MWh
A16: Blended cost for a factory operating 16 hours per day
A17: Grid hours available | B17: USD/kWh
A18: 0 | B18: =(A18*$B$2+(16-A18)*$B$5)/16 -> 0.37285714
A19: 1 | B19: =(A19*$B$2+(16-A19)*$B$5)/16 -> 0.35822704
A20: 2 | B20: =(A20*$B$2+(16-A20)*$B$5)/16 -> 0.34359694
A21: 3 | B21: =(A21*$B$2+(16-A21)*$B$5)/16 -> 0.32896684
A22: 4 | B22: =(A22*$B$2+(16-A22)*$B$5)/16 -> 0.31433673
A23: 5 | B23: =(A23*$B$2+(16-A23)*$B$5)/16 -> 0.29970663
A24: 6 | B24: =(A24*$B$2+(16-A24)*$B$5)/16 -> 0.28507653
A25: 7 | B25: =(A25*$B$2+(16-A25)*$B$5)/16 -> 0.27044643
A26: 8 | B26: =(A26*$B$2+(16-A26)*$B$5)/16 -> 0.25581633
A27: 9 | B27: =(A27*$B$2+(16-A27)*$B$5)/16 -> 0.24118622
A28: 10 | B28: =(A28*$B$2+(16-A28)*$B$5)/16 -> 0.22655612
A29: 11 | B29: =(A29*$B$2+(16-A29)*$B$5)/16 -> 0.21192602
... A34: 16 | B34: =(A34*$B$2+(16-A34)*$B$5)/16 -> 0.13877551

Sheet Analysis
A1: Static results exported from scripts/analysis.py (re-run the script to refresh). Not live formulas.
A3: Scenario | B3: Capex USD | C3: Project NPV USD | D3: Project IRR | E3: Equity NPV USD | F3: Equity IRR | G3: Payback (yrs) | H3: LCOE USD/kWh | I3: Min DSCR | J3: Definition
A4: Base case | B4: 32244276 | C4: 9926005.6 | D4: 0.20432152 | E4: 2800480.8 | F4: 0.28834832 | G4: 4.8232994 | H4: 0.078500576 | I4: 1.9096338 | J4: Assumptions as listed in Appendix A
A5: Upside | B5: 29664734 | C5: 19177146 | D5: 0.25749623 | E5: 8987272.2 | F5: 0.40203229 | G5: 3.8924498 | H5: 0.06890589 | I5: 2.4084928 | J5: Yield +4%, capex -8%, no FX loss, collection 99%, opex -10%
A6: Downside | B6: 37080917 | C6: -5770892.1 | D6: 0.12641144 | E6: -7753802 | F6: 0.13913432 | G6: 7.2856463 | H6: 0.097464412 | I6: 1.2277341 | J6: P90 yield (x0.928), capex +15%, FX loss 8%, collection 93%, opex +15%
A7: Severe stress | B7: 40305345 | C7: -18996740 | D7: 0.06430845 | E7: -16777619 | F7: 0.025328338 | G7: 10.698882 | H7: 0.11219763 | I7: 0.80972415 | J7: P90 yield, capex +25%, FX loss 13%, collection 90%, opex +30%, debt 11.5%, no PPA indexation
A8: Grid sale under Decision 154 | B8: 32244276 | C8: -20852381 | D8: 0.011218641 | E8: -16740793 | F8: -0.037639906 | G8: 20.345352 | H8: 0.072695482 | I8: 0.56244796 | J8: All output sold to the state utility at 0.04 USD/kWh flat, no wheeling, full collection
A9: PV + 20 MW / 80 MWh BESS | B9: 45444276 | C9: 819430 | D9: 0.15667128 | E9: -4424021.2 | F9: 0.19387903 | G9: 6.0838249 | H9: 0.10944199 | I9: 1.3682979 | J9: BESS charged from PV, evening energy at 0.16 USD/kWh
A11: Tornado driver | B11: NPV adverse | C11: NPV favourable | D11: Eq IRR adverse | E11: Eq IRR favourable | F11: Min DSCR adverse | G11: Min DSCR favourable
A12: PPA tariff (0.085 / 0.115 USD/kWh) | B12: 1555123.4 | C12: 18296888 | D12: 0.20340476 | E12: 0.3753769 | F12: 1.5283703 | G12: 2.2908973
A13: Capex (+20% / -10%) | B13: 3055830 | C13: 13361093 | D13: 0.21287996 | E13: 0.33994329 | F13: 1.5766987 | G13: 2.1315905
A14: FX conversion loss (13% / 0%) | B14: 4172821.9 | C14: 11651961 | D14: 0.22963598 | E14: 0.30617941 | F14: 1.647597 | G14: 1.9882448
A15: Opex (+30% / -20%) | B15: 5781301.1 | C15: 12689142 | D15: 0.24690912 | E15: 0.3160292 | F15: 1.7106496 | G15: 2.0422899
A16: Energy yield (P90 / +5%) | B16: 6172110.9 | C16: 12550438 | D16: 0.24984863 | E16: 0.31552934 | F16: 1.7394708 | G16: 2.0285986
A17: Collection rate (90% / 99%) | B17: 5898777.1 | C17: 11076642 | D17: 0.24711128 | E17: 0.30022699 | F17: 1.7262081 | G17: 1.9620411
A18: Interest rate (11.5% / 8.5%) | B18: 7318448.3 | C18: 11603919 | D18: 0.26895177 | E18: 0.29964657 | F18: 1.7357959 | G18: 2.0243461
A19: Availability (95% / 99.5%) | B19: 8060926.9 | C19: 10458885 | D19: 0.2691555 | E19: 0.29385232 | F19: 1.8250903 | G19: 1.9337891
A20: Income tax rate (15% / 0%) | B20: 9377230.9 | C20: 10999464 | D20: 0.28405499 | E20: 0.29673909 | F20: 1.8945215 | G20: 1.9398583
A21: Annual degradation (0.7% / 0.3%) | B21: 8963373.8 | C21: 10246883 | D21: 0.28242427 | E21: 0.29027429 | F21: 1.9096338 | G21: 1.9096338
A23: Monte Carlo (10,000 runs) | B23: Unmitigated | C23: With mitigants
A24: Project NPV P10 | B24: -3486159.4 | C24: 3657763.1
A25: Project NPV P50 | B25: 2634636.5 | C25: 8350414.8
A26: Project NPV P90 | B26: 8902670.3 | C26: 13134246
A27: Probability NPV < 0 | B27: 0.2994 | C27: 0.0129
A28: Equity IRR P10 | B28: 0.1568488 | C28: 0.22512165
A29: Equity IRR P50 | B29: 0.21329135 | C29: 0.2720109
A30: Equity IRR P90 | B30: 0.27751184 | C30: 0.32134822
A31: Probability equity IRR < cost of equity | B31: 0.7249 | C31: 0.2223
A32: Min DSCR P5 | B32: 1.2517923 | C32: 1.55943
A33: Probability min DSCR < 1.30 | B33: 0.0842 | C33: 0.0005
A34: Probability min DSCR < 1.15 | B34: 0.0137 | C34: 0
A36: Breakeven | B36: Value
A37: PPA tariff for project NPV = 0 | B37: 0.082213334
A38: PPA tariff for equity IRR = cost of equity | B38: 0.092138349
A39: PPA tariff for minimum DSCR = 1.30 | B39: 0.076015257
A40: Capex multiplier for project NPV = 0 | B40: 1.2889593
A41: FX conversion loss for project NPV = 0 | B41: 0.20253066
A42: BESS evening tariff for zero incremental NPV | B42: 0.22269591

Sheet Checks
A1: Check | B1: Excel value | C1: Expected / Python | D1: Difference | E1: Pass
A2: Sources equal uses: debt + equity - funding | B2: =x_debt+x_equity-x_funding -> 0 | C2: 0 | D2: =B2-C2 -> 0 | E2: =IF(ABS(D2)<0.01,"PASS","FAIL") -> PASS
A3: Capex lines sum to PV capex | B3: =(SUM(Capex!B2:B10)*(1+in_epc_margin)*(1+in_owners_pct+in_contingency)+in_c_dev_lump)*in_capex_mult-x_capex_pv -> 0 | C3: 0 | D3: =B3-C3 -> 0 | E3: =IF(ABS(D3)<0.01,"PASS","FAIL") -> PASS
A4: Debt fully repaid at end of tenor | B4: =CashFlow!$P$42 -> 0 | C4: 0 | D4: =B4-C4 -> 0 | E4: =IF(ABS(D4)<0.01,"PASS","FAIL") -> PASS
A5: Sum of principal equals debt | B5: =SUM(CashFlow!$E$41:$AC$41)-x_debt -> 0 | C5: 0 | D5: =B5-C5 -> 0 | E5: =IF(ABS(D5)<0.01,"PASS","FAIL") -> PASS
A6: Equity cash flow = CFADS - debt service (all years) | B6: =SUM(CashFlow!$E$58:$AC$58)-SUM(CashFlow!$E$40:$AC$40)-SUM(CashFlow!$E$60:$AC$60) -> 0 | C6: 0 | D6: =B6-C6 -> 0 | E6: =IF(ABS(D6)<0.01,"PASS","FAIL") -> PASS
A7: Project NPV at project IRR equals zero | B7: =CashFlow!$D$63+NPV(x_irr,CashFlow!$E$63:$AC$63) -> 0 | C7: 0 | D7: =B7-C7 -> 0 | E7: =IF(ABS(D7)<1,"PASS","FAIL") -> PASS
A8: Equity NPV at equity IRR equals zero | B8: =CashFlow!$D$60+NPV(x_irr_eq,CashFlow!$E$60:$AC$60) -> 0 | C8: 0 | D8: =B8-C8 -> 0 | E8: =IF(ABS(D8)<1,"PASS","FAIL") -> PASS
A9: Working capital released by final year | B9: =SUM(CashFlow!$E$55:$AC$55) -> 0 | C9: 0 | D9: =B9-C9 -> 0 | E9: =IF(ABS(D9)<0.01,"PASS","FAIL") -> PASS
A10: No negative tax paid | B10: =MIN(CashFlow!$E$51:$AC$51) -> 87769.422 | C10: 0 | D10: =B10 -> 87769.422 | E10: =IF(B10>=0,"PASS","FAIL") -> PASS
A11: No negative energy | B11: =MIN(CashFlow!$E$14:$AC$14) -> 87389.835 | C11: 0 | D11: =B11 -> 87389.835 | E11: =IF(B11>=0,"PASS","FAIL") -> PASS
A12: Gearing equals input | B12: =x_gear-in_gearing -> 0 | C12: 0 | D12: =B12-C12 -> 0 | E12: =IF(ABS(D12)<0.01,"PASS","FAIL") -> PASS
A13: Minimum DSCR above lock-up covenant | B13: =x_min_dscr-in_dscr_lockup -> 0.75963379 | C13: 0 | D13: =B13 -> 0.75963379 | E13: =IF(B13>=0,"PASS","FAIL") -> PASS
A14: Python: total capex | B14: =x_capex -> 32244276 | C14: 32244276 | D14: =IF(C14=0,B14,B14/C14-1) -> 0 | E14: =IF(ABS(D14)<0.000001,"PASS","FAIL") -> PASS
A15: Python: senior debt | B15: =x_debt -> 20170111 | C15: 20170111 | D15: =IF(C15=0,B15,B15/C15-1) -> 0 | E15: =IF(ABS(D15)<0.000001,"PASS","FAIL") -> PASS
A16: Python: year-1 energy (MWh) | B16: =x_e1 -> 96773.978 | C16: 96773.978 | D16: =IF(C16=0,B16,B16/C16-1) -> 0 | E16: =IF(ABS(D16)<0.000001,"PASS","FAIL") -> PASS
A17: Python: year-1 revenue | B17: =x_rev1 -> 9105463.6 | C17: 9105463.6 | D17: =IF(C17=0,B17,B17/C17-1) -> 0 | E17: =IF(ABS(D17)<0.000001,"PASS","FAIL") -> PASS
A18: Python: year-1 EBITDA | B18: =x_ebitda1 -> 7129967.2 | C18: 7129967.2 | D18: =IF(C18=0,B18,B18/C18-1) -> 0 | E18: =IF(ABS(D18)<0.000001,"PASS","FAIL") -> PASS
A19: Python: project NPV | B19: =x_npv -> 9926005.6 | C19: 9926005.6 | D19: =IF(C19=0,B19,B19/C19-1) -> 0 | E19: =IF(ABS(D19)<0.000001,"PASS","FAIL") -> PASS
A20: Python: project IRR | B20: =x_irr -> 0.20432152 | C20: 0.20432152 | D20: =IF(C20=0,B20,B20/C20-1) -> -1.9317881e-14 | E20: =IF(ABS(D20)<0.000001,"PASS","FAIL") -> PASS
A21: Python: equity NPV | B21: =x_npv_eq -> 2800480.8 | C21: 2800480.8 | D21: =IF(C21=0,B21,B21/C21-1) -> 0 | E21: =IF(ABS(D21)<0.000001,"PASS","FAIL") -> PASS
A22: Python: equity IRR | B22: =x_irr_eq -> 0.28834832 | C22: 0.28834832 | D22: =IF(C22=0,B22,B22/C22-1) -> -1.831868e-14 | E22: =IF(ABS(D22)<0.000001,"PASS","FAIL") -> PASS
A23: Python: project payback | B23: =x_pb -> 4.8232994 | C23: 4.8232994 | D23: =IF(C23=0,B23,B23/C23-1) -> 0 | E23: =IF(ABS(D23)<0.000001,"PASS","FAIL") -> PASS
A24: Python: equity payback | B24: =x_pb_eq -> 3.6127465 | C24: 3.6127465 | D24: =IF(C24=0,B24,B24/C24-1) -> 0 | E24: =IF(ABS(D24)<0.000001,"PASS","FAIL") -> PASS
A25: Python: LCOE at WACC | B25: =x_lcoe -> 0.078500576 | C25: 0.078500576 | D25: =IF(C25=0,B25,B25/C25-1) -> 0 | E25: =IF(ABS(D25)<0.000001,"PASS","FAIL") -> PASS
A26: Python: minimum DSCR | B26: =x_min_dscr -> 1.9096338 | C26: 1.9096338 | D26: =IF(C26=0,B26,B26/C26-1) -> 0 | E26: =IF(ABS(D26)<0.000001,"PASS","FAIL") -> PASS
A27: Python: average DSCR | B27: =x_avg_dscr -> 2.3568506 | C27: 2.3568506 | D27: =IF(C27=0,B27,B27/C27-1) -> 0 | E27: =IF(ABS(D27)<0.000001,"PASS","FAIL") -> PASS
A28: Python: LLCR | B28: =x_llcr -> 2.341825 | C28: 2.341825 | D28: =IF(C28=0,B28,B28/C28-1) -> 0 | E28: =IF(ABS(D28)<0.000001,"PASS","FAIL") -> PASS
A29: Python: WACC | B29: =x_wacc -> 0.1536005 | C29: 0.1536005 | D29: =IF(C29=0,B29,B29/C29-1) -> 0 | E29: =IF(ABS(D29)<0.000001,"PASS","FAIL") -> PASS
A31: Overall result | E31: =IF(COUNTIF(E2:E29,"PASS")=28,"ALL PASS","CHECK FAILURES") -> ALL PASS
A32: Python checks compare against data/results.json for the base case (bess_on = 0, multipliers = 1).

Sheet Sources
A1: ID | B1: Title | C1: Publisher | D1: Date | E1: URL | F1: Used for
A2: S01 | B2: PVGIS 5.3 PVcalc: fixed mounting, optimal tilt, 36.27N 37.30E (SARAH3 2005-2023) | C2: European Commission Joint Research Centre | D2: 2026-10-14 (retrieved) | E2: https://re.jrc.ec.europa.eu/api/v5_3/PVcalc?lat=36.27&lon=37.30&peakpower=1&loss=14&optimalangles=1&outputformat=json | F2: Specific yield 1,654.5 kWh/kWp; monthly yield; losses; tracker comparison
A3: S02 | B3: PVGIS 5.3 seriescalc hourly PV output 2019-2023, 31 deg tilt | C3: European Commission Joint Research Centre | D3: 2026-10-14 (retrieved) | E3: https://re.jrc.ec.europa.eu/api/v5_3/seriescalc?lat=36.27&lon=37.30&peakpower=1&loss=14&angle=31&aspect=1&startyear=2019&endyear=2023&pvcalculation=1&outputformat=csv | F3: Hourly profiles, clipping loss, BESS dispatch simulation
A4: S03 | B4: NASA POWER climatology API v2.10.1 (Jan 2001 - Dec 2025), ALLSKY_SFC_SW_DWN and T2M | C4: NASA Langley Research Center | D4: 2026-10-14 (retrieved) | E4: https://power.larc.nasa.gov/api/temporal/climatology/point?parameters=ALLSKY_SFC_SW_DWN,T2M&community=RE&longitude=37.30&latitude=36.27&format=JSON | F4: Irradiance and temperature cross-check
A5: S04 | B5: Global Solar Atlas long-term averages (Solargis model v2.2.68, data updated 2026-04-01) | C5: World Bank Group / ESMAP / Solargis | D5: 2026-10-14 (retrieved) | E5: https://api.globalsolaratlas.info/data/lta?loc=36.27,37.30 | F5: GHI, GTI, PVOUT cross-check
A6: S05 | B6: PV spot price: module, cell, wafer and polysilicon prices (week of 30 Sep 2026) | C6: InfoLink Consulting | D6: 2026-09-30 | E6: https://infolink-group.com/spot-price/ | F6: TOPCon module price 0.114 USD/W (non-China markets)
A7: S06 | B7: Renewable Power Generation Costs in 2025 (reported by PV Tech, 2 Jul 2026) | C7: IRENA; PV Tech | D7: 2026-07-02 | E7: https://www.pv-tech.org/solar-pv-lcoe-ticks-marginally-upwards-2025-irena/ | F7: Global utility PV installed cost 667 USD/kW and LCOE 44 USD/MWh (2025)
A8: S07 | B8: Battery storage system prices continue to fall sharply, BNEF and Ember reports find | C8: Energy-Storage.News (BNEF ESS Cost Survey 2025; Ember) | D8: 2025-12-16 | E8: https://www.energy-storage.news/battery-storage-system-prices-continue-to-fall-sharply-bnef-and-ember-reports-find/ | F8: Turnkey BESS 117 USD/kWh (BNEF); 125 USD/kWh all-in ex China/US (Ember, Oct 2025)
A9: S08 | B9: PowerChina wraps up record 102 GW solar equipment procurement tender | C9: pv magazine | D9: 2024-12-13 | E9: https://www.pv-magazine.com/2024/12/13/powerchina-wraps-up-record-102-gw-solar-equipment-procurement-tender/ | F9: String inverter bids 0.012-0.025 USD/W (China)
A10: S09 | B10: Limited Warranty, linear bifacial module (Rev. EN 2025-09-19) | C10: JinkoSolar | D10: 2025-09-19 | E10: https://www.jinkosolar.com/uploads/LIMITED%20WARRANTY%20REV.EN20250919-LINEAR-BIFACIAL%20MODULE.pdf | F10: Degradation: 1.0% year 1, 0.4%/yr thereafter
A11: S10 | B11: Annual Technology Baseline 2024: Utility-Scale PV | C11: National Renewable Energy Laboratory (NREL) | D11: 2024 | E11: https://atb.nrel.gov/electricity/2024/utility-scale_pv | F11: Fixed O&M benchmark 22 USD/kWac-yr
A12: S11 | B12: Ministry of Energy Decisions 686 and 687 on electricity tariffs (effective 1 Nov 2025); Enab Baladi coverage | C12: Ministry of Energy via Syrian Memory archive; Al-Fedaa; Enab Baladi | D12: 2025-10-30 | E12: https://syrianmemory.org/archive/documents/6949bb0ffc0b99dfa82ef97a | F12: Industrial tariff 1,700 old SYP/kWh; heavy industry 1,800; prior 1,500
... A41: S40 | B41: Establishing renewable energy companies in Syria 2026 | C41: Gars Legal (law firm commentary) | D41: 2026-09-28 | E41: https://garslegal.com/renewable-energy-company-formation-syria/ | F41: Direct B2B sales in industrial cities; licensing steps (commentary, to be confirmed by counsel)
