Workbook

Sheet Cover
B2: Bank of Aleppo Commercial (BAC) — Corporate Credit Model
B3: Borrower: Qalaa Olive & Laurel Industries LLC | Term Loan USD 2.4m + Revolver USD 0.9m
B4: Prepared by: Yamen Agha, Credit Analyst (portfolio case study) | Units: USD '000 unless stated
B6: DISCLAIMER | C6: All names, companies, the bank and every figure in this workbook are FICTIONAL and for illustration only. Bank of Aleppo Commercial is not a real bank; Qalaa Olive & Laurel Industries LLC is not a real company. Macro references describe the general post-2025 Syrian context. This is not a real credit decision or investment advice.
B8: Sheet | C8: What it does
B9: Dashboard | C9: Key outputs: facilities, DSCR by scenario, leverage, LTV, rating, checks, charts
B10: Assumptions | C10: All inputs: facility terms, projection drivers, scenario shocks (blue cells)
B11: IS / BS / CF | C11: Three years of historical statements (FY2023–FY2025) with FY2022 opening balance sheet; CF derived from BS movements
B12: Ratios | C12: Profitability, liquidity, leverage, coverage and efficiency ratios
B13: Debt_Schedule | C13: Term loan, revolver and existing loan schedules: balances, interest, principal
B14: Projections | C14: Five-year base case plus Downside, FX shock and Combined severe stress cases with DSCR and covenant tests
B15: Sensitivity | C15: FY2028 DSCR grid: sales decline x SYP depreciation, fully formula-driven
B16: Collateral | C16: Market values, haircuts, lending values, LTV and coverage
B17: Scorecard | C17: Internal risk rating scorecard (weighted factors -> BAC grade)
B18: Checks | C18: Integrity checks: balance sheet balances, cash ties, grid reconciles, loans repaid
B21: Colour code
B22: 1,000 | C22: Hard-coded input / assumption
B23: 1,000 | C23: Formula
B24: 1,000 | C24: Link to another sheet

Sheet Dashboard
A1: Dashboard – Key Credit Metrics
A2: Qalaa Olive & Laurel Industries LLC (fictional) | Bank of Aleppo Commercial (fictional) | USD '000
A4: Facilities
A5: Facility A – Term loan | B5: =Assumptions!$C$12 -> 2400
A6: Facility B – Revolver limit | B6: =Assumptions!$C$17 -> 900
A7: Total exposure | B7: =Assumptions!$C$12+Assumptions!$C$17 -> 3300
A8: Pro-forma Debt / EBITDA at drawdown | B8: =Scorecard!C8 -> 1.7254389
A9: LTV on market value | B9: =Collateral!C15 -> 0.39864641
A10: LTV on lending value | B10: =Collateral!C16 -> 0.72083683
A11: Collateral coverage | B11: =Collateral!C17 -> 1.3872765
A12: Internal rating | B12: =Scorecard!C27 -> 4
A13: Scorecard total | B13: =Scorecard!E22 -> 6.5
A14: All integrity checks pass | B14: =Checks!C16 -> ALL PASS
A16: DSCR by scenario
A17: Scenario | B17: FY2027 | C17: FY2028 | D17: FY2029 | E17: FY2030 | F17: FY2031 | G17: Minimum
A18: Base | B18: =Projections!D30 -> 3.0390471 | C18: =Projections!E30 -> 1.7735813 | D18: =Projections!F30 -> 2.6645642 | E18: =Projections!G30 -> 2.9830747 | F18: =Projections!H30 -> 3.3181605 | G18: =Projections!I30 -> 1.7735813
A19: Downside | B19: =Projections!D55 -> 2.4469773 | C19: =Projections!E55 -> 1.271525 | D19: =Projections!F55 -> 1.9212111 | E19: =Projections!G55 -> 2.1604047 | F19: =Projections!H55 -> 2.4159244 | G19: =Projections!I55 -> 1.271525
A20: FX shock | B20: =Projections!D80 -> 2.481905 | C20: =Projections!E80 -> 1.2864675 | D20: =Projections!F80 -> 1.963608 | E20: =Projections!G80 -> 2.1929108 | F20: =Projections!H80 -> 2.432405 | G20: =Projections!I80 -> 1.2864675
A21: Combined | B21: =Projections!D105 -> 1.6263219 | C21: =Projections!E105 -> 0.78037882 | D21: =Projections!F105 -> 1.2114563 | E21: =Projections!G105 -> 1.3470426 | F21: =Projections!H105 -> 1.4861509 | G21: =Projections!I105 -> 0.78037882
A22: Covenant minimum | B22: =Assumptions!$C$51 -> 1.25 | C22: =Assumptions!$C$51 -> 1.25 | D22: =Assumptions!$C$51 -> 1.25 | E22: =Assumptions!$C$51 -> 1.25 | F22: =Assumptions!$C$51 -> 1.25
A24: Base case revenue & EBITDA
A25: USD '000 | B25: FY2027 | C25: FY2028 | D25: FY2029 | E25: FY2030 | F25: FY2031
A26: Revenue | B26: =Projections!D15 -> 10898.92 | C26: =Projections!E15 -> 12206.79 | D26: =Projections!F15 -> 12931.569 | E26: =Projections!G15 -> 13578.147 | F26: =Projections!H15 -> 14121.273
A27: EBITDA | B27: =Projections!D19 -> 2440.2522 | C27: =Projections!E19 -> 2958.9524 | D27: =Projections!F19 -> 3110.8237 | E27: =Projections!G19 -> 3228.9515 | F27: =Projections!H19 -> 3304.2342
A28: Total debt (year end) | B28: =Debt_Schedule!D26 -> 3230 | C28: =Debt_Schedule!E26 -> 2430 | D28: =Debt_Schedule!F26 -> 1830 | E28: =Debt_Schedule!G26 -> 1230 | F28: =Debt_Schedule!H26 -> 630

Sheet Assumptions
A1: Assumptions & Inputs
A2: Blue cells are inputs. Change them and every sheet recalculates. USD '000.
A4: 1. General
A5: Corporate income tax rate (assumed) | B5: Illustrative effective rate | C5: 0.2
A6: Export share of revenue (projection) | B6: Gulf, Iraq, Jordan, EU | C6: 0.58
A7: Share of operating costs paid in SYP | B7: Wages, local services | C7: 0.65
A8: Net working capital, % of revenue | B8: FY2025 actual ~28% | C8: 0.27
A9: Maintenance capex, % of revenue | C9: 0.02
A11: 2. Proposed BAC facilities
A12: Facility A – Term loan amount | B12: Equipment + solar PV | C12: 2400
A13: Total project cost | B13: 75% debt / 25% sponsor equity | C13: 3200
A14: Facility A – all-in rate (3M Term SOFR 3.75% + 6.00%) | B14: Floor 9.25% | C14: 0.0975
A15: Facility A – principal grace (years) | B15: Interest-only in FY2027 | C15: 1
A16: Facility A – amortisation period (years) | B16: 16 equal quarterly instalments | C16: 4
A17: Facility B – Revolver limit | B17: Harvest stock + export receivables | C17: 900
A18: Facility B – all-in rate (3M Term SOFR 3.75% + 5.25%) | B18: Floor 8.75% | C18: 0.09
A19: Facility B – average utilisation | C19: 0.7
A20: Facility B – commitment fee on undrawn | C20: 0.005
A21: Arrangement fee (both facilities) | B21: Paid at signing | C21: 0.01
A22: DSRA – quarters of debt service held in cash | B22: Pledged to BAC | C22: 1
A24: 3. Existing debt (permitted)
A25: Existing term loan – balance at drawdown (end FY2026E) | B25: Other local lender | C25: 400
A26: Existing term loan – annual repayment | B26: Matures FY2028 | C26: 200
A27: Existing term loan – rate | C27: 0.1
A29: 4. Projection drivers (base case)
A30: Driver | B30: Note | C30: FY2026E | D30: FY2027 | E30: FY2028 | F30: FY2029 | G30: FY2030 | H30: FY2031
A31: Core revenue FY2026E (existing lines) | B31: 8M-2026 run-rate | C31: 9700
A32: Core revenue growth | B32: Volume + price | D32: 0.06 | E32: 0.06 | F32: 0.05 | G32: 0.05 | H32: 0.04
A33: New-line revenue uplift on core | B33: Ramp-up of bottling line | C33: 0 | D33: 0.06 | E33: 0.12 | F33: 0.13 | G33: 0.13 | H33: 0.13
A34: Raw materials, packaging & labour, % revenue | B34: Premium Gulf packaging | C34: 0.605 | D34: 0.61 | E34: 0.61 | F34: 0.61 | G34: 0.61 | H34: 0.61
A35: Energy cost, % revenue | B35: Solar PV from mid-FY2027 | C35: 0.088 | D35: 0.068 | E35: 0.053 | F35: 0.053 | G35: 0.053 | H35: 0.053
A36: Operating expenses FY2026E | C36: 990
A37: Operating expense growth | D37: 0.08 | E37: 0.08 | F37: 0.08 | G37: 0.08 | H37: 0.08
A38: D&A – existing asset base | C38: 380 | D38: 380 | E38: 380 | F38: 380 | G38: 380 | H38: 380
A39: Useful life of new equipment (years) | D39: 10 | E39: 10 | F39: 10 | G39: 10 | H39: 10
A41: 5. Stress scenarios (applied FY2027–FY2031)
A42: Shock parameter | B42: Note | C42: Base | D42: Downside | E42: FX shock | F42: Combined
A43: Sales volume change vs base | C43: 0 | D43: -0.1 | E43: 0 | F43: -0.15
A44: SYP depreciation vs USD | B44: +50% = USD/SYP rate rises 50% | C44: 0 | D44: 0 | E44: 0.5 | F44: 0.4
A45: Price pass-through of FX move (domestic) | B45: Share recovered via SYP price rises | C45: 0.5 | D45: 0.5 | E45: 0.5 | F45: 0.5
...

Sheet IS
A1: Historical Income Statement
A2: Audited, FY ending 31 December. USD '000. Fictional.
A4: USD '000 | B4: Note | D4: FY2023 | E4: FY2024 | F4: FY2025
A5: Revenue | D5: 6180 | E5: 7420 | F5: 8860
A6: of which export share | D6: 0.48 | E6: 0.52 | F6: 0.55
A7: Raw materials & packaging | D7: -3460 | E7: -4085 | F7: -4785
A8: Direct labour | D8: -420 | E8: -480 | F8: -540
A9: Energy (diesel generators & grid) | D9: -690 | E9: -770 | F9: -805
A10: Gross profit | D10: =SUM(D5,D7:D9) -> 1610 | E10: =SUM(E5,E7:E9) -> 2085 | F10: =SUM(F5,F7:F9) -> 2730
A11: Selling, general & admin (incl. export logistics) | D11: -610 | E11: -745 | F11: -890
A12: EBITDA | D12: =D10+D11 -> 1000 | E12: =E10+E11 -> 1340 | F12: =F10+F11 -> 1840
A13: Depreciation & amortisation | D13: -300 | E13: -330 | F13: -360
A14: EBIT | D14: =D12+D13 -> 700 | E14: =E12+E13 -> 1010 | F14: =F12+F13 -> 1480
A15: Interest expense | D15: -170 | E15: -150 | F15: -125
A16: Net FX translation loss | D16: -60 | E16: -40 | F16: -20
A17: Profit before tax | D17: =D14+D15+D16 -> 470 | E17: =E14+E15+E16 -> 820 | F17: =F14+F15+F16 -> 1335
A18: Income tax | B18: PBT x tax rate | D18: =-D17*Assumptions!$C$5 -> -94 | E18: =-E17*Assumptions!$C$5 -> -164 | F18: =-F17*Assumptions!$C$5 -> -267
A19: Net income | D19: =D17+D18 -> 376 | E19: =E17+E18 -> 656 | F19: =F17+F18 -> 1068
A20: Dividends paid | D20: -80 | E20: -120 | F20: -220
A22: Margins
A23: Gross margin | D23: =D10/D5 -> 0.2605178 | E23: =E10/E5 -> 0.2809973 | F23: =F10/F5 -> 0.30812641
A24: EBITDA margin | D24: =D12/D5 -> 0.1618123 | E24: =E12/E5 -> 0.18059299 | F24: =F12/F5 -> 0.20767494
A25: Net margin | D25: =D19/D5 -> 0.060841424 | E25: =E19/E5 -> 0.088409704 | F25: =F19/F5 -> 0.12054176
A26: Revenue growth | E26: =E5/D5-1 -> 0.20064725 | F26: =F5/E5-1 -> 0.19407008

Sheet BS
A1: Historical Balance Sheet
A2: 31 December. FY2022 shown as opening position. Cash is linked from the cash flow statement. USD '000.
A4: USD '000 | B4: Note | C4: FY2022 | D4: FY2023 | E4: FY2024 | F4: FY2025
A5: Assets
A6: Cash & bank balances | B6: FY2023+ = CF closing cash | C6: 300 | D6: =CF!D26 -> 341 | E6: =CF!E26 -> 287 | F6: =CF!F26 -> 555
A7: Trade receivables | C7: 950 | D7: 1050 | E7: 1240 | F7: 1420
A8: Inventories (olive oil, olives, soap) | C8: 1500 | D8: 1640 | E8: 1880 | F8: 2120
A9: Prepayments & other current assets | C9: 150 | D9: 170 | E9: 190 | F9: 220
A10: Total current assets | C10: =SUM(C6:C9) -> 2900 | D10: =SUM(D6:D9) -> 3201 | E10: =SUM(E6:E9) -> 3597 | F10: =SUM(F6:F9) -> 4315
A11: Property, plant & equipment, net | B11: Prior + capex – D&A | C11: 2900 | D11: =C11-CF!D15+IS!D13 -> 2850 | E11: =D11-CF!E15+IS!E13 -> 2940 | F11: =E11-CF!F15+IS!F13 -> 2960
A12: TOTAL ASSETS | C12: =C10+C11 -> 5800 | D12: =D10+D11 -> 6051 | E12: =E10+E11 -> 6537 | F12: =F10+F11 -> 7275
A14: Liabilities & equity
A15: Trade payables | C15: 700 | D15: 770 | E15: 890 | F15: 990
A16: Accruals & tax payable | C16: 200 | D16: 235 | E16: 265 | F16: 305
A17: Short-term bank debt (to be refinanced by BAC revolver) | C17: 600 | D17: 650 | E17: 650 | F17: 600
A18: Total current liabilities | C18: =SUM(C15:C17) -> 1500 | D18: =SUM(D15:D17) -> 1655 | E18: =SUM(E15:E17) -> 1805 | F18: =SUM(F15:F17) -> 1895
A19: Long-term bank debt (incl. current portion) | C19: 1200 | D19: 1000 | E19: 800 | F19: 600
A20: Total liabilities | C20: =C18+C19 -> 2700 | D20: =D18+D19 -> 2655 | E20: =E18+E19 -> 2605 | F20: =F18+F19 -> 2495
A21: Share capital | C21: 2000 | D21: 2000 | E21: 2000 | F21: 2000
A22: Retained earnings | B22: Prior + NI – dividends | C22: 1100 | D22: =C22+IS!D19+IS!D20 -> 1396 | E22: =D22+IS!E19+IS!E20 -> 1932 | F22: =E22+IS!F19+IS!F20 -> 2780
A23: Total equity | C23: =C21+C22 -> 3100 | D23: =D21+D22 -> 3396 | E23: =E21+E22 -> 3932 | F23: =F21+F22 -> 4780
A24: TOTAL LIABILITIES & EQUITY | C24: =C20+C23 -> 5800 | D24: =D20+D23 -> 6051 | E24: =E20+E23 -> 6537 | F24: =F20+F23 -> 7275
A26: Balance check (assets – L&E) | C26: =ROUND(C12-C24,6) -> 0 | D26: =ROUND(D12-D24,6) -> 0 | E26: =ROUND(E12-E24,6) -> 0 | F26: =ROUND(F12-F24,6) -> 0
A27: Total bank debt | C27: =C17+C19 -> 1800 | D27: =D17+D19 -> 1650 | E27: =E17+E19 -> 1450 | F27: =F17+F19 -> 1200
A28: Net working capital (ex cash, ex debt) | C28: =C7+C8+C9-C15-C16 -> 1700 | D28: =D7+D8+D9-D15-D16 -> 1855 | E28: =E7+E8+E9-E15-E16 -> 2155 | F28: =F7+F8+F9-F15-F16 -> 2465

Sheet CF
A1: Historical Cash Flow Statement (indirect)
A2: Derived from income statement and balance sheet movements. USD '000.
A4: USD '000 | B4: Note | D4: FY2023 | E4: FY2024 | F4: FY2025
A5: Operating activities
A6: Net income | D6: =IS!D19 -> 376 | E6: =IS!E19 -> 656 | F6: =IS!F19 -> 1068
A7: Add back: D&A | D7: =-IS!D13 -> 300 | E7: =-IS!E13 -> 330 | F7: =-IS!F13 -> 360
A8: (Increase) / decrease in receivables | D8: =BS!C7-BS!D7 -> -100 | E8: =BS!D7-BS!E7 -> -190 | F8: =BS!E7-BS!F7 -> -180
A9: (Increase) / decrease in inventories | D9: =BS!C8-BS!D8 -> -140 | E9: =BS!D8-BS!E8 -> -240 | F9: =BS!E8-BS!F8 -> -240
A10: (Increase) / decrease in other current assets | D10: =BS!C9-BS!D9 -> -20 | E10: =BS!D9-BS!E9 -> -20 | F10: =BS!E9-BS!F9 -> -30
A11: Increase / (decrease) in payables | D11: =BS!D15-BS!C15 -> 70 | E11: =BS!E15-BS!D15 -> 120 | F11: =BS!F15-BS!E15 -> 100
A12: Increase / (decrease) in accruals | D12: =BS!D16-BS!C16 -> 35 | E12: =BS!E16-BS!D16 -> 30 | F12: =BS!F16-BS!E16 -> 40
A13: Cash flow from operations | D13: =SUM(D6:D12) -> 521 | E13: =SUM(E6:E12) -> 686 | F13: =SUM(F6:F12) -> 1118
A14: Investing activities
A15: Capital expenditure | D15: -250 | E15: -420 | F15: -380
A16: Cash flow from investing | D16: =D15 -> -250 | E16: =E15 -> -420 | F16: =F15 -> -380
A17: Financing activities
A18: Net change in short-term bank debt | D18: =BS!D17-BS!C17 -> 50 | E18: =BS!E17-BS!D17 -> 0 | F18: =BS!F17-BS!E17 -> -50
A19: Net change in long-term debt | D19: =BS!D19-BS!C19 -> -200 | E19: =BS!E19-BS!D19 -> -200 | F19: =BS!F19-BS!E19 -> -200
A20: Dividends paid | D20: =IS!D20 -> -80 | E20: =IS!E20 -> -120 | F20: =IS!F20 -> -220
A21: Share capital issued | D21: =BS!D21-BS!C21 -> 0 | E21: =BS!E21-BS!D21 -> 0 | F21: =BS!F21-BS!E21 -> 0
A22: Cash flow from financing | D22: =SUM(D18:D21) -> -230 | E22: =SUM(E18:E21) -> -320 | F22: =SUM(F18:F21) -> -470
A24: Net change in cash | D24: =D13+D16+D22 -> 41 | E24: =E13+E16+E22 -> -54 | F24: =F13+F16+F22 -> 268
A25: Opening cash | D25: =BS!C6 -> 300 | E25: =BS!D6 -> 341 | F25: =BS!E6 -> 287
A26: Closing cash | D26: =D25+D24 -> 341 | E26: =E25+E24 -> 287 | F26: =F25+F24 -> 555
A28: Free cash flow (CFO + capex) | D28: =D13+D15 -> 271 | E28: =E13+E15 -> 266 | F28: =F13+F15 -> 738
A29: Cash tie-out (CF closing – BS cash) | D29: =ROUND(D26-BS!D6,6) -> 0 | E29: =ROUND(E26-BS!E6,6) -> 0 | F29: =ROUND(F26-BS!F6,6) -> 0

Sheet Ratios
A1: Ratio Analysis
A2: Calculated from IS / BS / CF. Average balances not used (year-end basis) for simplicity.
A4: Ratio | B4: Formula | D4: FY2023 | E4: FY2024 | F4: FY2025
A5: Profitability
A6: Gross margin | B6: Gross profit / Revenue | D6: =IS!D10/IS!D5 -> 0.2605178 | E6: =IS!E10/IS!E5 -> 0.2809973 | F6: =IS!F10/IS!F5 -> 0.30812641
A7: EBITDA margin | B7: EBITDA / Revenue | D7: =IS!D12/IS!D5 -> 0.1618123 | E7: =IS!E12/IS!E5 -> 0.18059299 | F7: =IS!F12/IS!F5 -> 0.20767494
A8: Net margin | B8: Net income / Revenue | D8: =IS!D19/IS!D5 -> 0.060841424 | E8: =IS!E19/IS!E5 -> 0.088409704 | F8: =IS!F19/IS!F5 -> 0.12054176
A9: Return on assets | B9: Net income / Total assets | D9: =IS!D19/BS!D12 -> 0.06213849 | E9: =IS!E19/BS!E12 -> 0.10035184 | F9: =IS!F19/BS!F12 -> 0.14680412
A10: Return on equity | B10: Net income / Total equity | D10: =IS!D19/BS!D23 -> 0.11071849 | E10: =IS!E19/BS!E23 -> 0.16683622 | F10: =IS!F19/BS!F23 -> 0.22343096
A11: Liquidity
A12: Current ratio | B12: Current assets / Current liabilities | D12: =BS!D10/BS!D18 -> 1.934139 | E12: =BS!E10/BS!E18 -> 1.9927978 | F12: =BS!F10/BS!F18 -> 2.2770449
A13: Quick ratio | B13: (Current assets – Inventory) / CL | D13: =(BS!D10-BS!D8)/BS!D18 -> 0.94320242 | E13: =(BS!E10-BS!E8)/BS!E18 -> 0.95124654 | F13: =(BS!F10-BS!F8)/BS!F18 -> 1.1583113
A14: Cash ratio | B14: Cash / Current liabilities | D14: =BS!D6/BS!D18 -> 0.2060423 | E14: =BS!E6/BS!E18 -> 0.15900277 | F14: =BS!F6/BS!F18 -> 0.29287599
A15: Leverage
A16: Debt / Equity | B16: Total bank debt / Equity | D16: =BS!D27/BS!D23 -> 0.48586572 | E16: =BS!E27/BS!E23 -> 0.36876907 | F16: =BS!F27/BS!F23 -> 0.25104603
A17: Total Debt / EBITDA | B17: Total bank debt / EBITDA | D17: =BS!D27/IS!D12 -> 1.65 | E17: =BS!E27/IS!E12 -> 1.0820896 | F17: =BS!F27/IS!F12 -> 0.65217391
A18: Net Debt / EBITDA | B18: (Debt – Cash) / EBITDA | D18: =(BS!D27-BS!D6)/IS!D12 -> 1.309 | E18: =(BS!E27-BS!E6)/IS!E12 -> 0.86791045 | F18: =(BS!F27-BS!F6)/IS!F12 -> 0.35054348
A19: Liabilities / Total assets | B19: Total liabilities / Total assets | D19: =BS!D20/BS!D12 -> 0.43877045 | E19: =BS!E20/BS!E12 -> 0.39850084 | F19: =BS!F20/BS!F12 -> 0.34295533
A20: Coverage
A21: Interest cover (EBITDA) | B21: EBITDA / Interest | D21: =IS!D12/-IS!D15 -> 5.8823529 | E21: =IS!E12/-IS!E15 -> 8.9333333 | F21: =IS!F12/-IS!F15 -> 14.72
A22: Interest cover (EBIT) | B22: EBIT / Interest | D22: =IS!D14/-IS!D15 -> 4.1176471 | E22: =IS!E14/-IS!E15 -> 6.7333333 | F22: =IS!F14/-IS!F15 -> 11.84
A23: Historical DSCR | B23: (EBITDA – tax – maint. capex) / (interest + LT principal) | D23: =(IS!D12+IS!D18-Assumptions!$C$9*IS!D5)/(-IS!D15+200) -> 2.1145946 | E23: =(IS!E12+IS!E18-Assumptions!$C$9*IS!E5)/(-IS!E15+200) -> 2.936 | F23: =(IS!F12+IS!F18-Assumptions!$C$9*IS!F5)/(-IS!F15+200) -> 4.2947692
A24: Efficiency
A25: Days sales outstanding (DSO) | B25: Receivables / Revenue x 365 | D25: =BS!D7/IS!D5*365 -> 62.014563 | E25: =BS!E7/IS!E5*365 -> 60.997305 | F25: =BS!F7/IS!F5*365 -> 58.498871
A26: Days inventory outstanding (DIO) | B26: Inventory / COGS x 365 | D26: =BS!D8/-(IS!D7+IS!D8+IS!D9)*365 -> 130.98468 | E26: =BS!E8/-(IS!E7+IS!E8+IS!E9)*365 -> 128.62231 | F26: =BS!F8/-(IS!F7+IS!F8+IS!F9)*365 -> 126.23165
A27: Days payables outstanding (DPO) | B27: Payables / COGS x 365 | D27: =BS!D15/-(IS!D7+IS!D8+IS!D9)*365 -> 61.498906 | E27: =BS!E15/-(IS!E7+IS!E8+IS!E9)*365 -> 60.890347 | F27: =BS!F15/-(IS!F7+IS!F8+IS!F9)*365 -> 58.947798
A28: Cash conversion cycle | B28: DSO + DIO – DPO | D28: =D25+D26-D27 -> 131.50034 | E28: =E25+E26-E27 -> 128.72926 | F28: =F25+F26-F27 -> 125.78272
A29: Asset turnover | B29: Revenue / Total assets | D29: =IS!D5/BS!D12 -> 1.0213188 | E29: =IS!E5/BS!E12 -> 1.1350773 | F29: =IS!F5/BS!F12 -> 1.2178694
A30: Net working capital / Revenue | B30: NWC / Revenue | D30: =BS!D28/IS!D5 -> 0.30016181 | E30: =BS!E28/IS!E5 -> 0.29043127 | F30: =BS!F28/IS!F5 -> 0.2782167
A31: Cash conversion (CFO / Net income) | B31: CFO / Net income | D31: =CF!D13/IS!D19 -> 1.3856383 | E31: =CF!E13/IS!E19 -> 1.0457317 | F31: =CF!F13/IS!F19 -> 1.0468165

Sheet Debt_Schedule
A1: Debt Schedule
A2: Facility A drawn Nov-2026 (end FY2026E). Interest on opening balance (conservative). USD '000.
A4: USD '000 | B4: Note | C4: FY2026E | D4: FY2027 | E4: FY2028 | F4: FY2029 | G4: FY2030 | H4: FY2031
A5: Year index | C5: 0 | D5: 1 | E5: 2 | F5: 3 | G5: 4 | H5: 5
A6: Facility A – Term loan
A7: Opening balance | C7: 0 | D7: =C10 -> 2400 | E7: =D10 -> 2400 | F7: =E10 -> 1800 | G7: =F10 -> 1200 | H7: =G10 -> 600
A8: Drawdown | C8: =Assumptions!$C$12 -> 2400 | D8: 0 | E8: 0 | F8: 0 | G8: 0 | H8: 0
A9: Scheduled repayment | B9: Grace then straight-line | C9: 0 | D9: =IF(D5<=Assumptions!$C$15,0,MIN(D7,Assumptions!$C$12/Assumptions!$C$16)) -> 0 | E9: =IF(E5<=Assumptions!$C$15,0,MIN(E7,Assumptions!$C$12/Assumptions!$C$16)) -> 600 | F9: =IF(F5<=Assumptions!$C$15,0,MIN(F7,Assumptions!$C$12/Assumptions!$C$16)) -> 600 | G9: =IF(G5<=Assumptions!$C$15,0,MIN(G7,Assumptions!$C$12/Assumptions!$C$16)) -> 600 | H9: =IF(H5<=Assumptions!$C$15,0,MIN(H7,Assumptions!$C$12/Assumptions!$C$16)) -> 600
A10: Closing balance | C10: =C7+C8-C9 -> 2400 | D10: =D7+D8-D9 -> 2400 | E10: =E7+E8-E9 -> 1800 | F10: =F7+F8-F9 -> 1200 | G10: =G7+G8-G9 -> 600 | H10: =H7+H8-H9 -> 0
A11: Interest (opening x rate) | D11: =D7*Assumptions!$C$14 -> 234 | E11: =E7*Assumptions!$C$14 -> 234 | F11: =F7*Assumptions!$C$14 -> 175.5 | G11: =G7*Assumptions!$C$14 -> 117 | H11: =H7*Assumptions!$C$14 -> 58.5
A12: Facility B – Revolving credit facility
A13: Average drawn balance | B13: Limit x utilisation | C13: =Assumptions!$C$17*Assumptions!$C$19 -> 630 | D13: =Assumptions!$C$17*Assumptions!$C$19 -> 630 | E13: =Assumptions!$C$17*Assumptions!$C$19 -> 630 | F13: =Assumptions!$C$17*Assumptions!$C$19 -> 630 | G13: =Assumptions!$C$17*Assumptions!$C$19 -> 630 | H13: =Assumptions!$C$17*Assumptions!$C$19 -> 630
A14: Interest on drawn | D14: =D13*Assumptions!$C$18 -> 56.7 | E14: =E13*Assumptions!$C$18 -> 56.7 | F14: =F13*Assumptions!$C$18 -> 56.7 | G14: =G13*Assumptions!$C$18 -> 56.7 | H14: =H13*Assumptions!$C$18 -> 56.7
A15: Commitment fee on undrawn | D15: =(Assumptions!$C$17-D13)*Assumptions!$C$20 -> 1.35 | E15: =(Assumptions!$C$17-E13)*Assumptions!$C$20 -> 1.35 | F15: =(Assumptions!$C$17-F13)*Assumptions!$C$20 -> 1.35 | G15: =(Assumptions!$C$17-G13)*Assumptions!$C$20 -> 1.35 | H15: =(Assumptions!$C$17-H13)*Assumptions!$C$20 -> 1.35
A16: Existing term loan (other lender)
A17: Opening balance | D17: =C19 -> 400 | E17: =D19 -> 200 | F17: =E19 -> 0 | G17: =F19 -> 0 | H17: =G19 -> 0
A18: Repayment | D18: =MIN(D17,Assumptions!$C$26) -> 200 | E18: =MIN(E17,Assumptions!$C$26) -> 200 | F18: =MIN(F17,Assumptions!$C$26) -> 0 | G18: =MIN(G17,Assumptions!$C$26) -> 0 | H18: =MIN(H17,Assumptions!$C$26) -> 0
A19: Closing balance | C19: =Assumptions!$C$25 -> 400 | D19: =D17-D18 -> 200 | E19: =E17-E18 -> 0 | F19: =F17-F18 -> 0 | G19: =G17-G18 -> 0 | H19: =H17-H18 -> 0
A20: Interest (opening x rate) | D20: =D17*Assumptions!$C$27 -> 40 | E20: =E17*Assumptions!$C$27 -> 20 | F20: =F17*Assumptions!$C$27 -> 0 | G20: =G17*Assumptions!$C$27 -> 0 | H20: =H17*Assumptions!$C$27 -> 0
A21: Totals
A22: Total interest & fees | D22: =D11+D14+D15+D20 -> 332.05 | E22: =E11+E14+E15+E20 -> 312.05 | F22: =F11+F14+F15+F20 -> 233.55 | G22: =G11+G14+G15+G20 -> 175.05 | H22: =H11+H14+H15+H20 -> 116.55
A23: Total scheduled principal | D23: =D9+D18 -> 200 | E23: =E9+E18 -> 800 | F23: =F9+F18 -> 600 | G23: =G9+G18 -> 600 | H23: =H9+H18 -> 600
A24: Total debt service (base rates) | D24: =D22+D23 -> 532.05 | E24: =E22+E23 -> 1112.05 | F24: =F22+F23 -> 833.55 | G24: =G22+G23 -> 775.05 | H24: =H22+H23 -> 716.55
A25: Interest-bearing base for rate shocks | B25: TL open + RCF drawn + existing open | D25: =D7+D13+D17 -> 3430 | E25: =E7+E13+E17 -> 3230 | F25: =F7+F13+F17 -> 2430 | G25: =G7+G13+G17 -> 1830 | H25: =H7+H13+H17 -> 1230
A26: Total debt at year end | B26: TL + RCF drawn + existing | C26: =C10+C13+C19 -> 3430 | D26: =D10+D13+D19 -> 3230 | E26: =E10+E13+E19 -> 2430 | F26: =F10+F13+F19 -> 1830 | G26: =G10+G13+G19 -> 1230 | H26: =H10+H13+H19 -> 630
A27: DSRA requirement (max annual DS / 4 x quarters) | C27: =MAX(D24:H24)/4*Assumptions!$C$22 -> 278.0125

Sheet Projections
A1: Five-Year Projections, DSCR & Stress Tests
A2: Base case plus three stress cases. Shocks from Assumptions section 5. USD '000.
A4: USD '000 | B4: Note | C4: FY2026E | D4: FY2027 | E4: FY2028 | F4: FY2029 | G4: FY2030 | H4: FY2031 | I4: Min / Max
A5: Base revenue & cost build (before shocks)
A6: Core revenue | C6: =Assumptions!C31 -> 9700 | D6: =C6*(1+Assumptions!D32) -> 10282 | E6: =D6*(1+Assumptions!E32) -> 10898.92 | F6: =E6*(1+Assumptions!F32) -> 11443.866 | G6: =F6*(1+Assumptions!G32) -> 12016.059 | H6: =G6*(1+Assumptions!H32) -> 12496.702
A7: Base revenue incl. new-line uplift | C7: =C6*(1+Assumptions!C33) -> 9700 | D7: =D6*(1+Assumptions!D33) -> 10898.92 | E7: =E6*(1+Assumptions!E33) -> 12206.79 | F7: =F6*(1+Assumptions!F33) -> 12931.569 | G7: =G6*(1+Assumptions!G33) -> 13578.147 | H7: =H6*(1+Assumptions!H33) -> 14121.273
A8: Base operating expenses | C8: =Assumptions!C36 -> 990 | D8: =C8*(1+Assumptions!D37) -> 1069.2 | E8: =D8*(1+Assumptions!E37) -> 1154.736 | F8: =E8*(1+Assumptions!F37) -> 1247.1149 | G8: =F8*(1+Assumptions!G37) -> 1346.8841 | H8: =G8*(1+Assumptions!H37) -> 1454.6348
A9: Depreciation (existing + new equipment) | C9: =Assumptions!C38 -> 380 | D9: =Assumptions!D38+Assumptions!$C$13/Assumptions!D39 -> 700 | E9: =Assumptions!E38+Assumptions!$C$13/Assumptions!E39 -> 700 | F9: =Assumptions!F38+Assumptions!$C$13/Assumptions!F39 -> 700 | G9: =Assumptions!G38+Assumptions!$C$13/Assumptions!G39 -> 700 | H9: =Assumptions!H38+Assumptions!$C$13/Assumptions!H39 -> 700
A10: FY2026E EBITDA (management estimate basis) | C10: =C7*(1-Assumptions!C34-Assumptions!C35)-C8 -> 1987.9
A12: Scenario: Base
A13: FX factor on SYP-priced items | B13: (1 + pass-through x dep) / (1 + dep) | D13: =(1+Assumptions!$C$45*Assumptions!$C$44)/(1+Assumptions!$C$44) -> 1 | E13: =(1+Assumptions!$C$45*Assumptions!$C$44)/(1+Assumptions!$C$44) -> 1 | F13: =(1+Assumptions!$C$45*Assumptions!$C$44)/(1+Assumptions!$C$44) -> 1 | G13: =(1+Assumptions!$C$45*Assumptions!$C$44)/(1+Assumptions!$C$44) -> 1 | H13: =(1+Assumptions!$C$45*Assumptions!$C$44)/(1+Assumptions!$C$44) -> 1
A14: Volume-adjusted revenue | B14: Base x (1 + sales shock) | D14: =D7*(1+Assumptions!$C$43) -> 10898.92 | E14: =E7*(1+Assumptions!$C$43) -> 12206.79 | F14: =F7*(1+Assumptions!$C$43) -> 12931.569 | G14: =G7*(1+Assumptions!$C$43) -> 13578.147 | H14: =H7*(1+Assumptions!$C$43) -> 14121.273
A15: Revenue (USD) | B15: Export + domestic x FX factor | D15: =D14*(Assumptions!$C$6+(1-Assumptions!$C$6)*D13) -> 10898.92 | E15: =E14*(Assumptions!$C$6+(1-Assumptions!$C$6)*E13) -> 12206.79 | F15: =F14*(Assumptions!$C$6+(1-Assumptions!$C$6)*F13) -> 12931.569 | G15: =G14*(Assumptions!$C$6+(1-Assumptions!$C$6)*G13) -> 13578.147 | H15: =H14*(Assumptions!$C$6+(1-Assumptions!$C$6)*H13) -> 14121.273
A16: Raw materials, packaging & labour | B16: USD-linked; on volume | D16: =-D14*(Assumptions!D34+Assumptions!$C$46) -> -6648.3412 | E16: =-E14*(Assumptions!E34+Assumptions!$C$46) -> -7446.1421 | F16: =-F14*(Assumptions!F34+Assumptions!$C$46) -> -7888.2568 | G16: =-G14*(Assumptions!G34+Assumptions!$C$46) -> -8282.6697 | H16: =-H14*(Assumptions!H34+Assumptions!$C$46) -> -8613.9765
A17: Energy | D17: =-D14*(Assumptions!D35+Assumptions!$C$47) -> -741.12656 | E17: =-E14*(Assumptions!E35+Assumptions!$C$47) -> -646.95989 | F17: =-F14*(Assumptions!F35+Assumptions!$C$47) -> -685.37313 | G17: =-G14*(Assumptions!G35+Assumptions!$C$47) -> -719.64179 | H17: =-H14*(Assumptions!H35+Assumptions!$C$47) -> -748.42746
A18: Operating expenses | B18: SYP share x FX factor | D18: =-D8*((1-Assumptions!$C$7)+Assumptions!$C$7*D13) -> -1069.2 | E18: =-E8*((1-Assumptions!$C$7)+Assumptions!$C$7*E13) -> -1154.736 | F18: =-F8*((1-Assumptions!$C$7)+Assumptions!$C$7*F13) -> -1247.1149 | G18: =-G8*((1-Assumptions!$C$7)+Assumptions!$C$7*G13) -> -1346.8841 | H18: =-H8*((1-Assumptions!$C$7)+Assumptions!$C$7*H13) -> -1454.6348
A19: EBITDA | D19: =SUM(D15:D18) -> 2440.2522 | E19: =SUM(E15:E18) -> 2958.9524 | F19: =SUM(F15:F18) -> 3110.8237 | G19: =SUM(G15:G18) -> 3228.9515 | H19: =SUM(H15:H18) -> 3304.2342 | I19: =MIN(D19:H19) -> 2440.2522
A20: EBITDA margin | D20: =D19/D15 -> 0.22389854 | E20: =E19/E15 -> 0.24240216 | F20: =F19/F15 -> 0.24056043 | G20: =G19/G15 -> 0.23780502 | H20: =H19/H15 -> 0.23398982
A21: Interest & fees | B21: Base + rate shock x debt | D21: =Debt_Schedule!D22+Assumptions!$C$48*Debt_Schedule!D25 -> 332.05 | E21: =Debt_Schedule!E22+Assumptions!$C$48*Debt_Schedule!E25 -> 312.05 | F21: =Debt_Schedule!F22+Assumptions!$C$48*Debt_Schedule!F25 -> 233.55 | G21: =Debt_Schedule!G22+Assumptions!$C$48*Debt_Schedule!G25 -> 175.05 | H21: =Debt_Schedule!H22+Assumptions!$C$48*Debt_Schedule!H25 -> 116.55
A22: Profit before tax | D22: =D19-D9-D21 -> 1408.2022 | E22: =E19-E9-E21 -> 1946.9024 | F22: =F19-F9-F21 -> 2177.2737 | G22: =G19-G9-G21 -> 2353.9015 | H22: =H19-H9-H21 -> 2487.6842
A23: Cash tax | B23: MAX(0, PBT x rate) | D23: =MAX(0,D22*Assumptions!$C$5) -> 281.64045 | E23: =MAX(0,E22*Assumptions!$C$5) -> 389.38047 | F23: =MAX(0,F22*Assumptions!$C$5) -> 435.45475 | G23: =MAX(0,G22*Assumptions!$C$5) -> 470.78029 | H23: =MAX(0,H22*Assumptions!$C$5) -> 497.53683
A24: Net income | D24: =D22-D23 -> 1126.5618 | E24: =E22-E23 -> 1557.5219 | F24: =F22-F23 -> 1741.819 | G24: =G22-G23 -> 1883.1212 | H24: =H22-H23 -> 1990.1473
A25: Maintenance capex | B25: % of revenue | D25: =Assumptions!$C$9*D15 -> 217.9784 | E25: =Assumptions!$C$9*E15 -> 244.13581 | F25: =Assumptions!$C$9*F15 -> 258.63137 | G25: =Assumptions!$C$9*G15 -> 271.56294 | H25: =Assumptions!$C$9*H15 -> 282.42546
A26: Increase in net working capital | B26: MAX(0, NWC% x revenue growth) | D26: =MAX(0,Assumptions!$C$8*(D15-$C$7)) -> 323.7084 | E26: =MAX(0,Assumptions!$C$8*(E15-D15)) -> 353.12501 | F26: =MAX(0,Assumptions!$C$8*(F15-E15)) -> 195.69011 | G26: =MAX(0,Assumptions!$C$8*(G15-F15)) -> 174.57618 | H26: =MAX(0,Assumptions!$C$8*(H15-G15)) -> 146.64399
A27: Cash flow available for debt service (CFADS) | B27: EBITDA – tax – capex – ΔNWC | D27: =D19-D23-D25-D26 -> 1616.925 | E27: =E19-E23-E25-E26 -> 1972.3111 | F27: =F19-F23-F25-F26 -> 2221.0475 | G27: =G19-G23-G25-G26 -> 2312.0321 | H27: =H19-H23-H25-H26 -> 2377.6279
A28: Scheduled principal | D28: =Debt_Schedule!D23 -> 200 | E28: =Debt_Schedule!E23 -> 800 | F28: =Debt_Schedule!F23 -> 600 | G28: =Debt_Schedule!G23 -> 600 | H28: =Debt_Schedule!H23 -> 600
A29: Total debt service | B29: Interest & fees + principal | D29: =D21+D28 -> 532.05 | E29: =E21+E28 -> 1112.05 | F29: =F21+F28 -> 833.55 | G29: =G21+G28 -> 775.05 | H29: =H21+H28 -> 716.55
A30: DSCR | B30: CFADS / debt service | D30: =D27/D29 -> 3.0390471 | E30: =E27/E29 -> 1.7735813 | F30: =F27/F29 -> 2.6645642 | G30: =G27/G29 -> 2.9830747 | H30: =H27/H29 -> 3.3181605 | I30: =MIN(D30:H30) -> 1.7735813
A31: CFADS headroom before DSCR = 1.0x | B31: 1 – 1/DSCR | D31: =1-1/D30 -> 0.67094949 | E31: =1-1/E30 -> 0.43616906 | F31: =1-1/F30 -> 0.62470411 | G31: =1-1/G30 -> 0.66477541 | H31: =1-1/H30 -> 0.6986282
A32: Total Debt / EBITDA | B32: Year-end debt / EBITDA | D32: =Debt_Schedule!D26/D19 -> 1.3236337 | E32: =Debt_Schedule!E26/E19 -> 0.82123661 | F32: =Debt_Schedule!F26/F19 -> 0.58826863 | G32: =Debt_Schedule!G26/G19 -> 0.38092861 | H32: =Debt_Schedule!H26/H19 -> 0.19066445 | I32: =MAX(D32:H32) -> 1.3236337
A33: Cumulative cash after debt service | D33: =0+D27-D29 -> 1084.875 | E33: =D33+E27-E29 -> 1945.1361 | F33: =E33+F27-F29 -> 3332.6336 | G33: =F33+G27-G29 -> 4869.6156 | H33: =G33+H27-H29 -> 6530.6935
A34: Covenant: DSCR ≥ minimum | D34: =IF(D30>=Assumptions!$C$51,"PASS","BREACH") -> PASS | E34: =IF(E30>=Assumptions!$C$51,"PASS","BREACH") -> PASS | F34: =IF(F30>=Assumptions!$C$51,"PASS","BREACH") -> PASS | G34: =IF(G30>=Assumptions!$C$51,"PASS","BREACH") -> PASS | H34: =IF(H30>=Assumptions!$C$51,"PASS","BREACH") -> PASS
A35: Covenant: Debt/EBITDA ≤ maximum | D35: =IF(D32<=Assumptions!$C$52,"PASS","BREACH") -> PASS | E35: =IF(E32<=Assumptions!$C$52,"PASS","BREACH") -> PASS | F35: =IF(F32<=Assumptions!$C$52,"PASS","BREACH") -> PASS | G35: =IF(G32<=Assumptions!$C$52,"PASS","BREACH") -> PASS | H35: =IF(H32<=Assumptions!$C$52,"PASS","BREACH") -> PASS
A37: Scenario: Downside
A38: FX factor on SYP-priced items | B38: (1 + pass-through x dep) / (1 + dep) | D38: =(1+Assumptions!$D$45*Assumptions!$D$44)/(1+Assumptions!$D$44) -> 1 | E38: =(1+Assumptions!$D$45*Assumptions!$D$44)/(1+Assumptions!$D$44) -> 1 | F38: =(1+Assumptions!$D$45*Assumptions!$D$44)/(1+Assumptions!$D$44) -> 1 | G38: =(1+Assumptions!$D$45*Assumptions!$D$44)/(1+Assumptions!$D$44) -> 1 | H38: =(1+Assumptions!$D$45*Assumptions!$D$44)/(1+Assumptions!$D$44) -> 1
A39: Volume-adjusted revenue | B39: Base x (1 + sales shock) | D39: =D7*(1+Assumptions!$D$43) -> 9809.028 | E39: =E7*(1+Assumptions!$D$43) -> 10986.111 | F39: =F7*(1+Assumptions!$D$43) -> 11638.412 | G39: =G7*(1+Assumptions!$D$43) -> 12220.332 | H39: =H7*(1+Assumptions!$D$43) -> 12709.146
A40: Revenue (USD) | B40: Export + domestic x FX factor | D40: =D39*(Assumptions!$C$6+(1-Assumptions!$C$6)*D38) -> 9809.028 | E40: =E39*(Assumptions!$C$6+(1-Assumptions!$C$6)*E38) -> 10986.111 | F40: =F39*(Assumptions!$C$6+(1-Assumptions!$C$6)*F38) -> 11638.412 | G40: =G39*(Assumptions!$C$6+(1-Assumptions!$C$6)*G38) -> 12220.332 | H40: =H39*(Assumptions!$C$6+(1-Assumptions!$C$6)*H38) -> 12709.146
A41: Raw materials, packaging & labour | B41: USD-linked; on volume | D41: =-D39*(Assumptions!D34+Assumptions!$D$46) -> -6130.6425 | E41: =-E39*(Assumptions!E34+Assumptions!$D$46) -> -6866.3196 | F41: =-F39*(Assumptions!F34+Assumptions!$D$46) -> -7274.0073 | G41: =-G39*(Assumptions!G34+Assumptions!$D$46) -> -7637.7077 | H41: =-H39*(Assumptions!H34+Assumptions!$D$46) -> -7943.216
A42: Energy | D42: =-D39*(Assumptions!D35+Assumptions!$D$47) -> -765.10418 | E42: =-E39*(Assumptions!E35+Assumptions!$D$47) -> -692.12502 | F42: =-F39*(Assumptions!F35+Assumptions!$D$47) -> -733.21994 | G42: =-G39*(Assumptions!G35+Assumptions!$D$47) -> -769.88094 | H42: =-H39*(Assumptions!H35+Assumptions!$D$47) -> -800.67617
A43: Operating expenses | B43: SYP share x FX factor | D43: =-D8*((1-Assumptions!$C$7)+Assumptions!$C$7*D38) -> -1069.2 | E43: =-E8*((1-Assumptions!$C$7)+Assumptions!$C$7*E38) -> -1154.736 | F43: =-F8*((1-Assumptions!$C$7)+Assumptions!$C$7*F38) -> -1247.1149 | G43: =-G8*((1-Assumptions!$C$7)+Assumptions!$C$7*G38) -> -1346.8841 | H43: =-H8*((1-Assumptions!$C$7)+Assumptions!$C$7*H38) -> -1454.6348
...

Sheet Sensitivity
A1: Sensitivity: FY2028 DSCR (first full amortisation year)
A2: Each cell recomputes CFADS / debt service for the sales change (rows) and SYP depreciation (columns). Other shocks off; base rates.
A4: FX pass-through used | B4: =Assumptions!$C$45 -> 0.5
A6: Sales change ↓ / SYP depreciation → | C6: 0 | D6: 0.2 | E6: 0.4 | F6: 0.6 | G6: 0.8
A7: 0 | C7: =((((Projections!$E$7*(1+$A7))*(Assumptions!$C$6+(1-Assumptions!$C$6)*((1+$B$4*C$6)/(1+C$6))))-(Projections!$E$7*(1+$A7))*(Assumptions!$E$34+Assumptions!$E$35)-Projections!$E$8*((1-Assumptions!$C$7)+Assumptions!$C$7*((1+$B$4*C$6)/(1+C$6))))-MAX(0,((((Projections!$E$7*(1+$A7))*(Assumptions!$C$6+(1-Assumptions!$C$6)*((1+$B$4*C$6)/(1+C$6))))-(Projections!$E$7*(1+$A7))*(Assumptions!$E$34+Assumptions!$E$35)-Projections!$E$8*((1-Assumptions!$C$7)+Assumptions!$C$7*((1+$B$4*C$6)/(1+C$6))))-Projections!$E$9-Debt_Schedule!$E$22)*Assumptions!$C$5)-Assumptions!$C$9*((Projections!$E$7*(1+$A7))*(Assumptions!$C$6+(1-Assumptions!$C$6)*((1+$B$4*C$6)/(1+C$6))))-MAX(0,Assumptions!$C$8*(((Projections!$E$7*(1+$A7))*(Assumptions!$C$6+(1-Assumptions!$C$6)*((1+$B$4*C$6)/(1+C$6))))-(Projections!$D$7*(1+$A7)*(Assumptions!$C$6+(1-Assumptions!$C$6)*((1+$B$4*C$6)/(1+C$6)))))))/Debt_Schedule!$E$24 -> 1.7735813 | D7: =((((Projections!$E$7*(1+$A7))*(Assumptions!$C$6+(1-Assumptions!$C$6)*((1+$B$4*D$6)/(1+D$6))))-(Projections!$E$7*(1+$A7))*(Assumptions!$E$34+Assumptions!$E$35)-Projections!$E$8*((1-Assumptions!$C$7)+Assumptions!$C$7*((1+$B$4*D$6)/(1+D$6))))-MAX(0,((((Projections!$E$7*(1+$A7))*(Assumptions!$C$6+(1-Assumptions!$C$6)*((1+$B$4*D$6)/(1+D$6))))-(Projections!$E$7*(1+$A7))*(Assumptions!$E$34+Assumptions!$E$35)-Projections!$E$8*((1-Assumptions!$C$7)+Assumptions!$C$7*((1+$B$4*D$6)/(1+D$6))))-Projections!$E$9-Debt_Schedule!$E$22)*Assumptions!$C$5)-Assumptions!$C$9*((Projections!$E$7*(1+$A7))*(Assumptions!$C$6+(1-Assumptions!$C$6)*((1+$B$4*D$6)/(1+D$6))))-MAX(0,Assumptions!$C$8*(((Projections!$E$7*(1+$A7))*(Assumptions!$C$6+(1-Assumptions!$C$6)*((1+$B$4*D$6)/(1+D$6))))-(Projections!$D$7*(1+$A7)*(Assumptions!$C$6+(1-Assumptions!$C$6)*((1+$B$4*D$6)/(1+D$6)))))))/Debt_Schedule!$E$24 -> 1.5300244 | E7: =((((Projections!$E$7*(1+$A7))*(Assumptions!$C$6+(1-Assumptions!$C$6)*((1+$B$4*E$6)/(1+E$6))))-(Projections!$E$7*(1+$A7))*(Assumptions!$E$34+Assumptions!$E$35)-Projections!$E$8*((1-Assumptions!$C$7)+Assumptions!$C$7*((1+$B$4*E$6)/(1+E$6))))-MAX(0,((((Projections!$E$7*(1+$A7))*(Assumptions!$C$6+(1-Assumptions!$C$6)*((1+$B$4*E$6)/(1+E$6))))-(Projections!$E$7*(1+$A7))*(Assumptions!$E$34+Assumptions!$E$35)-Projections!$E$8*((1-Assumptions!$C$7)+Assumptions!$C$7*((1+$B$4*E$6)/(1+E$6))))-Projections!$E$9-Debt_Schedule!$E$22)*Assumptions!$C$5)-Assumptions!$C$9*((Projections!$E$7*(1+$A7))*(Assumptions!$C$6+(1-Assumptions!$C$6)*((1+$B$4*E$6)/(1+E$6))))-MAX(0,Assumptions!$C$8*(((Projections!$E$7*(1+$A7))*(Assumptions!$C$6+(1-Assumptions!$C$6)*((1+$B$4*E$6)/(1+E$6))))-(Projections!$D$7*(1+$A7)*(Assumptions!$C$6+(1-Assumptions!$C$6)*((1+$B$4*E$6)/(1+E$6)))))))/Debt_Schedule!$E$24 -> 1.3560552 | F7: =((((Projections!$E$7*(1+$A7))*(Assumptions!$C$6+(1-Assumptions!$C$6)*((1+$B$4*F$6)/(1+F$6))))-(Projections!$E$7*(1+$A7))*(Assumptions!$E$34+Assumptions!$E$35)-Projections!$E$8*((1-Assumptions!$C$7)+Assumptions!$C$7*((1+$B$4*F$6)/(1+F$6))))-MAX(0,((((Projections!$E$7*(1+$A7))*(Assumptions!$C$6+(1-Assumptions!$C$6)*((1+$B$4*F$6)/(1+F$6))))-(Projections!$E$7*(1+$A7))*(Assumptions!$E$34+Assumptions!$E$35)-Projections!$E$8*((1-Assumptions!$C$7)+Assumptions!$C$7*((1+$B$4*F$6)/(1+F$6))))-Projections!$E$9-Debt_Schedule!$E$22)*Assumptions!$C$5)-Assumptions!$C$9*((Projections!$E$7*(1+$A7))*(Assumptions!$C$6+(1-Assumptions!$C$6)*((1+$B$4*F$6)/(1+F$6))))-MAX(0,Assumptions!$C$8*(((Projections!$E$7*(1+$A7))*(Assumptions!$C$6+(1-Assumptions!$C$6)*((1+$B$4*F$6)/(1+F$6))))-(Projections!$D$7*(1+$A7)*(Assumptions!$C$6+(1-Assumptions!$C$6)*((1+$B$4*F$6)/(1+F$6)))))))/Debt_Schedule!$E$24 -> 1.2255783 | G7: =((((Projections!$E$7*(1+$A7))*(Assumptions!$C$6+(1-Assumptions!$C$6)*((1+$B$4*G$6)/(1+G$6))))-(Projections!$E$7*(1+$A7))*(Assumptions!$E$34+Assumptions!$E$35)-Projections!$E$8*((1-Assumptions!$C$7)+Assumptions!$C$7*((1+$B$4*G$6)/(1+G$6))))-MAX(0,((((Projections!$E$7*(1+$A7))*(Assumptions!$C$6+(1-Assumptions!$C$6)*((1+$B$4*G$6)/(1+G$6))))-(Projections!$E$7*(1+$A7))*(Assumptions!$E$34+Assumptions!$E$35)-Projections!$E$8*((1-Assumptions!$C$7)+Assumptions!$C$7*((1+$B$4*G$6)/(1+G$6))))-Projections!$E$9-Debt_Schedule!$E$22)*Assumptions!$C$5)-Assumptions!$C$9*((Projections!$E$7*(1+$A7))*(Assumptions!$C$6+(1-Assumptions!$C$6)*((1+$B$4*G$6)/(1+G$6))))-MAX(0,Assumptions!$C$8*(((Projections!$E$7*(1+$A7))*(Assumptions!$C$6+(1-Assumptions!$C$6)*((1+$B$4*G$6)/(1+G$6))))-(Projections!$D$7*(1+$A7)*(Assumptions!$C$6+(1-Assumptions!$C$6)*((1+$B$4*G$6)/(1+G$6)))))))/Debt_Schedule!$E$24 -> 1.1240962
A8: -0.05 | C8: =((((Projections!$E$7*(1+$A8))*(Assumptions!$C$6+(1-Assumptions!$C$6)*((1+$B$4*C$6)/(1+C$6))))-(Projections!$E$7*(1+$A8))*(Assumptions!$E$34+Assumptions!$E$35)-Projections!$E$8*((1-Assumptions!$C$7)+Assumptions!$C$7*((1+$B$4*C$6)/(1+C$6))))-MAX(0,((((Projections!$E$7*(1+$A8))*(Assumptions!$C$6+(1-Assumptions!$C$6)*((1+$B$4*C$6)/(1+C$6))))-(Projections!$E$7*(1+$A8))*(Assumptions!$E$34+Assumptions!$E$35)-Projections!$E$8*((1-Assumptions!$C$7)+Assumptions!$C$7*((1+$B$4*C$6)/(1+C$6))))-Projections!$E$9-Debt_Schedule!$E$22)*Assumptions!$C$5)-Assumptions!$C$9*((Projections!$E$7*(1+$A8))*(Assumptions!$C$6+(1-Assumptions!$C$6)*((1+$B$4*C$6)/(1+C$6))))-MAX(0,Assumptions!$C$8*(((Projections!$E$7*(1+$A8))*(Assumptions!$C$6+(1-Assumptions!$C$6)*((1+$B$4*C$6)/(1+C$6))))-(Projections!$D$7*(1+$A8)*(Assumptions!$C$6+(1-Assumptions!$C$6)*((1+$B$4*C$6)/(1+C$6)))))))/Debt_Schedule!$E$24 -> 1.6524676 | D8: =((((Projections!$E$7*(1+$A8))*(Assumptions!$C$6+(1-Assumptions!$C$6)*((1+$B$4*D$6)/(1+D$6))))-(Projections!$E$7*(1+$A8))*(Assumptions!$E$34+Assumptions!$E$35)-Projections!$E$8*((1-Assumptions!$C$7)+Assumptions!$C$7*((1+$B$4*D$6)/(1+D$6))))-MAX(0,((((Projections!$E$7*(1+$A8))*(Assumptions!$C$6+(1-Assumptions!$C$6)*((1+$B$4*D$6)/(1+D$6))))-(Projections!$E$7*(1+$A8))*(Assumptions!$E$34+Assumptions!$E$35)-Projections!$E$8*((1-Assumptions!$C$7)+Assumptions!$C$7*((1+$B$4*D$6)/(1+D$6))))-Projections!$E$9-Debt_Schedule!$E$22)*Assumptions!$C$5)-Assumptions!$C$9*((Projections!$E$7*(1+$A8))*(Assumptions!$C$6+(1-Assumptions!$C$6)*((1+$B$4*D$6)/(1+D$6))))-MAX(0,Assumptions!$C$8*(((Projections!$E$7*(1+$A8))*(Assumptions!$C$6+(1-Assumptions!$C$6)*((1+$B$4*D$6)/(1+D$6))))-(Projections!$D$7*(1+$A8)*(Assumptions!$C$6+(1-Assumptions!$C$6)*((1+$B$4*D$6)/(1+D$6)))))))/Debt_Schedule!$E$24 -> 1.4233384 | E8: =((((Projections!$E$7*(1+$A8))*(Assumptions!$C$6+(1-Assumptions!$C$6)*((1+$B$4*E$6)/(1+E$6))))-(Projections!$E$7*(1+$A8))*(Assumptions!$E$34+Assumptions!$E$35)-Projections!$E$8*((1-Assumptions!$C$7)+Assumptions!$C$7*((1+$B$4*E$6)/(1+E$6))))-MAX(0,((((Projections!$E$7*(1+$A8))*(Assumptions!$C$6+(1-Assumptions!$C$6)*((1+$B$4*E$6)/(1+E$6))))-(Projections!$E$7*(1+$A8))*(Assumptions!$E$34+Assumptions!$E$35)-Projections!$E$8*((1-Assumptions!$C$7)+Assumptions!$C$7*((1+$B$4*E$6)/(1+E$6))))-Projections!$E$9-Debt_Schedule!$E$22)*Assumptions!$C$5)-Assumptions!$C$9*((Projections!$E$7*(1+$A8))*(Assumptions!$C$6+(1-Assumptions!$C$6)*((1+$B$4*E$6)/(1+E$6))))-MAX(0,Assumptions!$C$8*(((Projections!$E$7*(1+$A8))*(Assumptions!$C$6+(1-Assumptions!$C$6)*((1+$B$4*E$6)/(1+E$6))))-(Projections!$D$7*(1+$A8)*(Assumptions!$C$6+(1-Assumptions!$C$6)*((1+$B$4*E$6)/(1+E$6)))))))/Debt_Schedule!$E$24 -> 1.2596747 | F8: =((((Projections!$E$7*(1+$A8))*(Assumptions!$C$6+(1-Assumptions!$C$6)*((1+$B$4*F$6)/(1+F$6))))-(Projections!$E$7*(1+$A8))*(Assumptions!$E$34+Assumptions!$E$35)-Projections!$E$8*((1-Assumptions!$C$7)+Assumptions!$C$7*((1+$B$4*F$6)/(1+F$6))))-MAX(0,((((Projections!$E$7*(1+$A8))*(Assumptions!$C$6+(1-Assumptions!$C$6)*((1+$B$4*F$6)/(1+F$6))))-(Projections!$E$7*(1+$A8))*(Assumptions!$E$34+Assumptions!$E$35)-Projections!$E$8*((1-Assumptions!$C$7)+Assumptions!$C$7*((1+$B$4*F$6)/(1+F$6))))-Projections!$E$9-Debt_Schedule!$E$22)*Assumptions!$C$5)-Assumptions!$C$9*((Projections!$E$7*(1+$A8))*(Assumptions!$C$6+(1-Assumptions!$C$6)*((1+$B$4*F$6)/(1+F$6))))-MAX(0,Assumptions!$C$8*(((Projections!$E$7*(1+$A8))*(Assumptions!$C$6+(1-Assumptions!$C$6)*((1+$B$4*F$6)/(1+F$6))))-(Projections!$D$7*(1+$A8)*(Assumptions!$C$6+(1-Assumptions!$C$6)*((1+$B$4*F$6)/(1+F$6)))))))/Debt_Schedule!$E$24 -> 1.1369269 | G8: =((((Projections!$E$7*(1+$A8))*(Assumptions!$C$6+(1-Assumptions!$C$6)*((1+$B$4*G$6)/(1+G$6))))-(Projections!$E$7*(1+$A8))*(Assumptions!$E$34+Assumptions!$E$35)-Projections!$E$8*((1-Assumptions!$C$7)+Assumptions!$C$7*((1+$B$4*G$6)/(1+G$6))))-MAX(0,((((Projections!$E$7*(1+$A8))*(Assumptions!$C$6+(1-Assumptions!$C$6)*((1+$B$4*G$6)/(1+G$6))))-(Projections!$E$7*(1+$A8))*(Assumptions!$E$34+Assumptions!$E$35)-Projections!$E$8*((1-Assumptions!$C$7)+Assumptions!$C$7*((1+$B$4*G$6)/(1+G$6))))-Projections!$E$9-Debt_Schedule!$E$22)*Assumptions!$C$5)-Assumptions!$C$9*((Projections!$E$7*(1+$A8))*(Assumptions!$C$6+(1-Assumptions!$C$6)*((1+$B$4*G$6)/(1+G$6))))-MAX(0,Assumptions!$C$8*(((Projections!$E$7*(1+$A8))*(Assumptions!$C$6+(1-Assumptions!$C$6)*((1+$B$4*G$6)/(1+G$6))))-(Projections!$D$7*(1+$A8)*(Assumptions!$C$6+(1-Assumptions!$C$6)*((1+$B$4*G$6)/(1+G$6)))))))/Debt_Schedule!$E$24 -> 1.0414564
A9: -0.1 | C9: =((((Projections!$E$7*(1+$A9))*(Assumptions!$C$6+(1-Assumptions!$C$6)*((1+$B$4*C$6)/(1+C$6))))-(Projections!$E$7*(1+$A9))*(Assumptions!$E$34+Assumptions!$E$35)-Projections!$E$8*((1-Assumptions!$C$7)+Assumptions!$C$7*((1+$B$4*C$6)/(1+C$6))))-MAX(0,((((Projections!$E$7*(1+$A9))*(Assumptions!$C$6+(1-Assumptions!$C$6)*((1+$B$4*C$6)/(1+C$6))))-(Projections!$E$7*(1+$A9))*(Assumptions!$E$34+Assumptions!$E$35)-Projections!$E$8*((1-Assumptions!$C$7)+Assumptions!$C$7*((1+$B$4*C$6)/(1+C$6))))-Projections!$E$9-Debt_Schedule!$E$22)*Assumptions!$C$5)-Assumptions!$C$9*((Projections!$E$7*(1+$A9))*(Assumptions!$C$6+(1-Assumptions!$C$6)*((1+$B$4*C$6)/(1+C$6))))-MAX(0,Assumptions!$C$8*(((Projections!$E$7*(1+$A9))*(Assumptions!$C$6+(1-Assumptions!$C$6)*((1+$B$4*C$6)/(1+C$6))))-(Projections!$D$7*(1+$A9)*(Assumptions!$C$6+(1-Assumptions!$C$6)*((1+$B$4*C$6)/(1+C$6)))))))/Debt_Schedule!$E$24 -> 1.5313539 | D9: =((((Projections!$E$7*(1+$A9))*(Assumptions!$C$6+(1-Assumptions!$C$6)*((1+$B$4*D$6)/(1+D$6))))-(Projections!$E$7*(1+$A9))*(Assumptions!$E$34+Assumptions!$E$35)-Projections!$E$8*((1-Assumptions!$C$7)+Assumptions!$C$7*((1+$B$4*D$6)/(1+D$6))))-MAX(0,((((Projections!$E$7*(1+$A9))*(Assumptions!$C$6+(1-Assumptions!$C$6)*((1+$B$4*D$6)/(1+D$6))))-(Projections!$E$7*(1+$A9))*(Assumptions!$E$34+Assumptions!$E$35)-Projections!$E$8*((1-Assumptions!$C$7)+Assumptions!$C$7*((1+$B$4*D$6)/(1+D$6))))-Projections!$E$9-Debt_Schedule!$E$22)*Assumptions!$C$5)-Assumptions!$C$9*((Projections!$E$7*(1+$A9))*(Assumptions!$C$6+(1-Assumptions!$C$6)*((1+$B$4*D$6)/(1+D$6))))-MAX(0,Assumptions!$C$8*(((Projections!$E$7*(1+$A9))*(Assumptions!$C$6+(1-Assumptions!$C$6)*((1+$B$4*D$6)/(1+D$6))))-(Projections!$D$7*(1+$A9)*(Assumptions!$C$6+(1-Assumptions!$C$6)*((1+$B$4*D$6)/(1+D$6)))))))/Debt_Schedule!$E$24 -> 1.3166524 | E9: =((((Projections!$E$7*(1+$A9))*(Assumptions!$C$6+(1-Assumptions!$C$6)*((1+$B$4*E$6)/(1+E$6))))-(Projections!$E$7*(1+$A9))*(Assumptions!$E$34+Assumptions!$E$35)-Projections!$E$8*((1-Assumptions!$C$7)+Assumptions!$C$7*((1+$B$4*E$6)/(1+E$6))))-MAX(0,((((Projections!$E$7*(1+$A9))*(Assumptions!$C$6+(1-Assumptions!$C$6)*((1+$B$4*E$6)/(1+E$6))))-(Projections!$E$7*(1+$A9))*(Assumptions!$E$34+Assumptions!$E$35)-Projections!$E$8*((1-Assumptions!$C$7)+Assumptions!$C$7*((1+$B$4*E$6)/(1+E$6))))-Projections!$E$9-Debt_Schedule!$E$22)*Assumptions!$C$5)-Assumptions!$C$9*((Projections!$E$7*(1+$A9))*(Assumptions!$C$6+(1-Assumptions!$C$6)*((1+$B$4*E$6)/(1+E$6))))-MAX(0,Assumptions!$C$8*(((Projections!$E$7*(1+$A9))*(Assumptions!$C$6+(1-Assumptions!$C$6)*((1+$B$4*E$6)/(1+E$6))))-(Projections!$D$7*(1+$A9)*(Assumptions!$C$6+(1-Assumptions!$C$6)*((1+$B$4*E$6)/(1+E$6)))))))/Debt_Schedule!$E$24 -> 1.1632941 | F9: =((((Projections!$E$7*(1+$A9))*(Assumptions!$C$6+(1-Assumptions!$C$6)*((1+$B$4*F$6)/(1+F$6))))-(Projections!$E$7*(1+$A9))*(Assumptions!$E$34+Assumptions!$E$35)-Projections!$E$8*((1-Assumptions!$C$7)+Assumptions!$C$7*((1+$B$4*F$6)/(1+F$6))))-MAX(0,((((Projections!$E$7*(1+$A9))*(Assumptions!$C$6+(1-Assumptions!$C$6)*((1+$B$4*F$6)/(1+F$6))))-(Projections!$E$7*(1+$A9))*(Assumptions!$E$34+Assumptions!$E$35)-Projections!$E$8*((1-Assumptions!$C$7)+Assumptions!$C$7*((1+$B$4*F$6)/(1+F$6))))-Projections!$E$9-Debt_Schedule!$E$22)*Assumptions!$C$5)-Assumptions!$C$9*((Projections!$E$7*(1+$A9))*(Assumptions!$C$6+(1-Assumptions!$C$6)*((1+$B$4*F$6)/(1+F$6))))-MAX(0,Assumptions!$C$8*(((Projections!$E$7*(1+$A9))*(Assumptions!$C$6+(1-Assumptions!$C$6)*((1+$B$4*F$6)/(1+F$6))))-(Projections!$D$7*(1+$A9)*(Assumptions!$C$6+(1-Assumptions!$C$6)*((1+$B$4*F$6)/(1+F$6)))))))/Debt_Schedule!$E$24 -> 1.0482754 | G9: =((((Projections!$E$7*(1+$A9))*(Assumptions!$C$6+(1-Assumptions!$C$6)*((1+$B$4*G$6)/(1+G$6))))-(Projections!$E$7*(1+$A9))*(Assumptions!$E$34+Assumptions!$E$35)-Projections!$E$8*((1-Assumptions!$C$7)+Assumptions!$C$7*((1+$B$4*G$6)/(1+G$6))))-MAX(0,((((Projections!$E$7*(1+$A9))*(Assumptions!$C$6+(1-Assumptions!$C$6)*((1+$B$4*G$6)/(1+G$6))))-(Projections!$E$7*(1+$A9))*(Assumptions!$E$34+Assumptions!$E$35)-Projections!$E$8*((1-Assumptions!$C$7)+Assumptions!$C$7*((1+$B$4*G$6)/(1+G$6))))-Projections!$E$9-Debt_Schedule!$E$22)*Assumptions!$C$5)-Assumptions!$C$9*((Projections!$E$7*(1+$A9))*(Assumptions!$C$6+(1-Assumptions!$C$6)*((1+$B$4*G$6)/(1+G$6))))-MAX(0,Assumptions!$C$8*(((Projections!$E$7*(1+$A9))*(Assumptions!$C$6+(1-Assumptions!$C$6)*((1+$B$4*G$6)/(1+G$6))))-(Projections!$D$7*(1+$A9)*(Assumptions!$C$6+(1-Assumptions!$C$6)*((1+$B$4*G$6)/(1+G$6)))))))/Debt_Schedule!$E$24 -> 0.95881646
A10: -0.15 | C10: =((((Projections!$E$7*(1+$A10))*(Assumptions!$C$6+(1-Assumptions!$C$6)*((1+$B$4*C$6)/(1+C$6))))-(Projections!$E$7*(1+$A10))*(Assumptions!$E$34+Assumptions!$E$35)-Projections!$E$8*((1-Assumptions!$C$7)+Assumptions!$C$7*((1+$B$4*C$6)/(1+C$6))))-MAX(0,((((Projections!$E$7*(1+$A10))*(Assumptions!$C$6+(1-Assumptions!$C$6)*((1+$B$4*C$6)/(1+C$6))))-(Projections!$E$7*(1+$A10))*(Assumptions!$E$34+Assumptions!$E$35)-Projections!$E$8*((1-Assumptions!$C$7)+Assumptions!$C$7*((1+$B$4*C$6)/(1+C$6))))-Projections!$E$9-Debt_Schedule!$E$22)*Assumptions!$C$5)-Assumptions!$C$9*((Projections!$E$7*(1+$A10))*(Assumptions!$C$6+(1-Assumptions!$C$6)*((1+$B$4*C$6)/(1+C$6))))-MAX(0,Assumptions!$C$8*(((Projections!$E$7*(1+$A10))*(Assumptions!$C$6+(1-Assumptions!$C$6)*((1+$B$4*C$6)/(1+C$6))))-(Projections!$D$7*(1+$A10)*(Assumptions!$C$6+(1-Assumptions!$C$6)*((1+$B$4*C$6)/(1+C$6)))))))/Debt_Schedule!$E$24 -> 1.4102402 | D10: =((((Projections!$E$7*(1+$A10))*(Assumptions!$C$6+(1-Assumptions!$C$6)*((1+$B$4*D$6)/(1+D$6))))-(Projections!$E$7*(1+$A10))*(Assumptions!$E$34+Assumptions!$E$35)-Projections!$E$8*((1-Assumptions!$C$7)+Assumptions!$C$7*((1+$B$4*D$6)/(1+D$6))))-MAX(0,((((Projections!$E$7*(1+$A10))*(Assumptions!$C$6+(1-Assumptions!$C$6)*((1+$B$4*D$6)/(1+D$6))))-(Projections!$E$7*(1+$A10))*(Assumptions!$E$34+Assumptions!$E$35)-Projections!$E$8*((1-Assumptions!$C$7)+Assumptions!$C$7*((1+$B$4*D$6)/(1+D$6))))-Projections!$E$9-Debt_Schedule!$E$22)*Assumptions!$C$5)-Assumptions!$C$9*((Projections!$E$7*(1+$A10))*(Assumptions!$C$6+(1-Assumptions!$C$6)*((1+$B$4*D$6)/(1+D$6))))-MAX(0,Assumptions!$C$8*(((Projections!$E$7*(1+$A10))*(Assumptions!$C$6+(1-Assumptions!$C$6)*((1+$B$4*D$6)/(1+D$6))))-(Projections!$D$7*(1+$A10)*(Assumptions!$C$6+(1-Assumptions!$C$6)*((1+$B$4*D$6)/(1+D$6)))))))/Debt_Schedule!$E$24 -> 1.2099663 | E10: =((((Projections!$E$7*(1+$A10))*(Assumptions!$C$6+(1-Assumptions!$C$6)*((1+$B$4*E$6)/(1+E$6))))-(Projections!$E$7*(1+$A10))*(Assumptions!$E$34+Assumptions!$E$35)-Projections!$E$8*((1-Assumptions!$C$7)+Assumptions!$C$7*((1+$B$4*E$6)/(1+E$6))))-MAX(0,((((Projections!$E$7*(1+$A10))*(Assumptions!$C$6+(1-Assumptions!$C$6)*((1+$B$4*E$6)/(1+E$6))))-(Projections!$E$7*(1+$A10))*(Assumptions!$E$34+Assumptions!$E$35)-Projections!$E$8*((1-Assumptions!$C$7)+Assumptions!$C$7*((1+$B$4*E$6)/(1+E$6))))-Projections!$E$9-Debt_Schedule!$E$22)*Assumptions!$C$5)-Assumptions!$C$9*((Projections!$E$7*(1+$A10))*(Assumptions!$C$6+(1-Assumptions!$C$6)*((1+$B$4*E$6)/(1+E$6))))-MAX(0,Assumptions!$C$8*(((Projections!$E$7*(1+$A10))*(Assumptions!$C$6+(1-Assumptions!$C$6)*((1+$B$4*E$6)/(1+E$6))))-(Projections!$D$7*(1+$A10)*(Assumptions!$C$6+(1-Assumptions!$C$6)*((1+$B$4*E$6)/(1+E$6)))))))/Debt_Schedule!$E$24 -> 1.0669136 | F10: =((((Projections!$E$7*(1+$A10))*(Assumptions!$C$6+(1-Assumptions!$C$6)*((1+$B$4*F$6)/(1+F$6))))-(Projections!$E$7*(1+$A10))*(Assumptions!$E$34+Assumptions!$E$35)-Projections!$E$8*((1-Assumptions!$C$7)+Assumptions!$C$7*((1+$B$4*F$6)/(1+F$6))))-MAX(0,((((Projections!$E$7*(1+$A10))*(Assumptions!$C$6+(1-Assumptions!$C$6)*((1+$B$4*F$6)/(1+F$6))))-(Projections!$E$7*(1+$A10))*(Assumptions!$E$34+Assumptions!$E$35)-Projections!$E$8*((1-Assumptions!$C$7)+Assumptions!$C$7*((1+$B$4*F$6)/(1+F$6))))-Projections!$E$9-Debt_Schedule!$E$22)*Assumptions!$C$5)-Assumptions!$C$9*((Projections!$E$7*(1+$A10))*(Assumptions!$C$6+(1-Assumptions!$C$6)*((1+$B$4*F$6)/(1+F$6))))-MAX(0,Assumptions!$C$8*(((Projections!$E$7*(1+$A10))*(Assumptions!$C$6+(1-Assumptions!$C$6)*((1+$B$4*F$6)/(1+F$6))))-(Projections!$D$7*(1+$A10)*(Assumptions!$C$6+(1-Assumptions!$C$6)*((1+$B$4*F$6)/(1+F$6)))))))/Debt_Schedule!$E$24 -> 0.959624 | G10: =((((Projections!$E$7*(1+$A10))*(Assumptions!$C$6+(1-Assumptions!$C$6)*((1+$B$4*G$6)/(1+G$6))))-(Projections!$E$7*(1+$A10))*(Assumptions!$E$34+Assumptions!$E$35)-Projections!$E$8*((1-Assumptions!$C$7)+Assumptions!$C$7*((1+$B$4*G$6)/(1+G$6))))-MAX(0,((((Projections!$E$7*(1+$A10))*(Assumptions!$C$6+(1-Assumptions!$C$6)*((1+$B$4*G$6)/(1+G$6))))-(Projections!$E$7*(1+$A10))*(Assumptions!$E$34+Assumptions!$E$35)-Projections!$E$8*((1-Assumptions!$C$7)+Assumptions!$C$7*((1+$B$4*G$6)/(1+G$6))))-Projections!$E$9-Debt_Schedule!$E$22)*Assumptions!$C$5)-Assumptions!$C$9*((Projections!$E$7*(1+$A10))*(Assumptions!$C$6+(1-Assumptions!$C$6)*((1+$B$4*G$6)/(1+G$6))))-MAX(0,Assumptions!$C$8*(((Projections!$E$7*(1+$A10))*(Assumptions!$C$6+(1-Assumptions!$C$6)*((1+$B$4*G$6)/(1+G$6))))-(Projections!$D$7*(1+$A10)*(Assumptions!$C$6+(1-Assumptions!$C$6)*((1+$B$4*G$6)/(1+G$6)))))))/Debt_Schedule!$E$24 -> 0.87617656
A11: -0.2 | C11: =((((Projections!$E$7*(1+$A11))*(Assumptions!$C$6+(1-Assumptions!$C$6)*((1+$B$4*C$6)/(1+C$6))))-(Projections!$E$7*(1+$A11))*(Assumptions!$E$34+Assumptions!$E$35)-Projections!$E$8*((1-Assumptions!$C$7)+Assumptions!$C$7*((1+$B$4*C$6)/(1+C$6))))-MAX(0,((((Projections!$E$7*(1+$A11))*(Assumptions!$C$6+(1-Assumptions!$C$6)*((1+$B$4*C$6)/(1+C$6))))-(Projections!$E$7*(1+$A11))*(Assumptions!$E$34+Assumptions!$E$35)-Projections!$E$8*((1-Assumptions!$C$7)+Assumptions!$C$7*((1+$B$4*C$6)/(1+C$6))))-Projections!$E$9-Debt_Schedule!$E$22)*Assumptions!$C$5)-Assumptions!$C$9*((Projections!$E$7*(1+$A11))*(Assumptions!$C$6+(1-Assumptions!$C$6)*((1+$B$4*C$6)/(1+C$6))))-MAX(0,Assumptions!$C$8*(((Projections!$E$7*(1+$A11))*(Assumptions!$C$6+(1-Assumptions!$C$6)*((1+$B$4*C$6)/(1+C$6))))-(Projections!$D$7*(1+$A11)*(Assumptions!$C$6+(1-Assumptions!$C$6)*((1+$B$4*C$6)/(1+C$6)))))))/Debt_Schedule!$E$24 -> 1.2891265 | D11: =((((Projections!$E$7*(1+$A11))*(Assumptions!$C$6+(1-Assumptions!$C$6)*((1+$B$4*D$6)/(1+D$6))))-(Projections!$E$7*(1+$A11))*(Assumptions!$E$34+Assumptions!$E$35)-Projections!$E$8*((1-Assumptions!$C$7)+Assumptions!$C$7*((1+$B$4*D$6)/(1+D$6))))-MAX(0,((((Projections!$E$7*(1+$A11))*(Assumptions!$C$6+(1-Assumptions!$C$6)*((1+$B$4*D$6)/(1+D$6))))-(Projections!$E$7*(1+$A11))*(Assumptions!$E$34+Assumptions!$E$35)-Projections!$E$8*((1-Assumptions!$C$7)+Assumptions!$C$7*((1+$B$4*D$6)/(1+D$6))))-Projections!$E$9-Debt_Schedule!$E$22)*Assumptions!$C$5)-Assumptions!$C$9*((Projections!$E$7*(1+$A11))*(Assumptions!$C$6+(1-Assumptions!$C$6)*((1+$B$4*D$6)/(1+D$6))))-MAX(0,Assumptions!$C$8*(((Projections!$E$7*(1+$A11))*(Assumptions!$C$6+(1-Assumptions!$C$6)*((1+$B$4*D$6)/(1+D$6))))-(Projections!$D$7*(1+$A11)*(Assumptions!$C$6+(1-Assumptions!$C$6)*((1+$B$4*D$6)/(1+D$6)))))))/Debt_Schedule!$E$24 -> 1.1032803 | E11: =((((Projections!$E$7*(1+$A11))*(Assumptions!$C$6+(1-Assumptions!$C$6)*((1+$B$4*E$6)/(1+E$6))))-(Projections!$E$7*(1+$A11))*(Assumptions!$E$34+Assumptions!$E$35)-Projections!$E$8*((1-Assumptions!$C$7)+Assumptions!$C$7*((1+$B$4*E$6)/(1+E$6))))-MAX(0,((((Projections!$E$7*(1+$A11))*(Assumptions!$C$6+(1-Assumptions!$C$6)*((1+$B$4*E$6)/(1+E$6))))-(Projections!$E$7*(1+$A11))*(Assumptions!$E$34+Assumptions!$E$35)-Projections!$E$8*((1-Assumptions!$C$7)+Assumptions!$C$7*((1+$B$4*E$6)/(1+E$6))))-Projections!$E$9-Debt_Schedule!$E$22)*Assumptions!$C$5)-Assumptions!$C$9*((Projections!$E$7*(1+$A11))*(Assumptions!$C$6+(1-Assumptions!$C$6)*((1+$B$4*E$6)/(1+E$6))))-MAX(0,Assumptions!$C$8*(((Projections!$E$7*(1+$A11))*(Assumptions!$C$6+(1-Assumptions!$C$6)*((1+$B$4*E$6)/(1+E$6))))-(Projections!$D$7*(1+$A11)*(Assumptions!$C$6+(1-Assumptions!$C$6)*((1+$B$4*E$6)/(1+E$6)))))))/Debt_Schedule!$E$24 -> 0.97053303 | F11: =((((Projections!$E$7*(1+$A11))*(Assumptions!$C$6+(1-Assumptions!$C$6)*((1+$B$4*F$6)/(1+F$6))))-(Projections!$E$7*(1+$A11))*(Assumptions!$E$34+Assumptions!$E$35)-Projections!$E$8*((1-Assumptions!$C$7)+Assumptions!$C$7*((1+$B$4*F$6)/(1+F$6))))-MAX(0,((((Projections!$E$7*(1+$A11))*(Assumptions!$C$6+(1-Assumptions!$C$6)*((1+$B$4*F$6)/(1+F$6))))-(Projections!$E$7*(1+$A11))*(Assumptions!$E$34+Assumptions!$E$35)-Projections!$E$8*((1-Assumptions!$C$7)+Assumptions!$C$7*((1+$B$4*F$6)/(1+F$6))))-Projections!$E$9-Debt_Schedule!$E$22)*Assumptions!$C$5)-Assumptions!$C$9*((Projections!$E$7*(1+$A11))*(Assumptions!$C$6+(1-Assumptions!$C$6)*((1+$B$4*F$6)/(1+F$6))))-MAX(0,Assumptions!$C$8*(((Projections!$E$7*(1+$A11))*(Assumptions!$C$6+(1-Assumptions!$C$6)*((1+$B$4*F$6)/(1+F$6))))-(Projections!$D$7*(1+$A11)*(Assumptions!$C$6+(1-Assumptions!$C$6)*((1+$B$4*F$6)/(1+F$6)))))))/Debt_Schedule!$E$24 -> 0.87097258 | G11: =((((Projections!$E$7*(1+$A11))*(Assumptions!$C$6+(1-Assumptions!$C$6)*((1+$B$4*G$6)/(1+G$6))))-(Projections!$E$7*(1+$A11))*(Assumptions!$E$34+Assumptions!$E$35)-Projections!$E$8*((1-Assumptions!$C$7)+Assumptions!$C$7*((1+$B$4*G$6)/(1+G$6))))-MAX(0,((((Projections!$E$7*(1+$A11))*(Assumptions!$C$6+(1-Assumptions!$C$6)*((1+$B$4*G$6)/(1+G$6))))-(Projections!$E$7*(1+$A11))*(Assumptions!$E$34+Assumptions!$E$35)-Projections!$E$8*((1-Assumptions!$C$7)+Assumptions!$C$7*((1+$B$4*G$6)/(1+G$6))))-Projections!$E$9-Debt_Schedule!$E$22)*Assumptions!$C$5)-Assumptions!$C$9*((Projections!$E$7*(1+$A11))*(Assumptions!$C$6+(1-Assumptions!$C$6)*((1+$B$4*G$6)/(1+G$6))))-MAX(0,Assumptions!$C$8*(((Projections!$E$7*(1+$A11))*(Assumptions!$C$6+(1-Assumptions!$C$6)*((1+$B$4*G$6)/(1+G$6))))-(Projections!$D$7*(1+$A11)*(Assumptions!$C$6+(1-Assumptions!$C$6)*((1+$B$4*G$6)/(1+G$6)))))))/Debt_Schedule!$E$24 -> 0.79353667
